ERROR 2024-11-29 15:12:11,444 log 20384 18228 Internal Server Error: /api/user/me/
Traceback (most recent call last):
  File "D:\Azamat\projects\back-end\learning\байэл\baia_messanger\venv\Lib\site-packages\rest_framework\views.py", line 506, in dispatch
    response = handler(request, *args, **kwargs)
               ^^^^^^^^^^^^^^^^^^^^^^^^^^^^^^^^^
  File "D:\Azamat\projects\back-end\learning\байэл\baia_messanger\api\v1\views\views.py", line 19, in put
    serializer.is_valid(raise_exception=True)
  File "D:\Azamat\projects\back-end\learning\байэл\baia_messanger\venv\Lib\site-packages\rest_framework\serializers.py", line 231, in is_valid
    raise ValidationError(self.errors)
rest_framework.exceptions.ValidationError: {'non_field_errors': [ErrorDetail(string='Недопустимые данные. Ожидался dictionary, но был получен Request.', code='invalid')]}

During handling of the above exception, another exception occurred:

Traceback (most recent call last):
  File "D:\Azamat\projects\back-end\learning\байэл\baia_messanger\venv\Lib\site-packages\rest_framework\settings.py", line 179, in import_from_string
    return import_string(val)
           ^^^^^^^^^^^^^^^^^^
  File "D:\Azamat\projects\back-end\learning\байэл\baia_messanger\venv\Lib\site-packages\django\utils\module_loading.py", line 30, in import_string
    return cached_import(module_path, class_name)
           ^^^^^^^^^^^^^^^^^^^^^^^^^^^^^^^^^^^^^^
  File "D:\Azamat\projects\back-end\learning\байэл\baia_messanger\venv\Lib\site-packages\django\utils\module_loading.py", line 15, in cached_import
    module = import_module(module_path)
             ^^^^^^^^^^^^^^^^^^^^^^^^^^
  File "C:\Program Files\Python312\Lib\importlib\__init__.py", line 90, in import_module
    return _bootstrap._gcd_import(name[level:], package, level)
           ^^^^^^^^^^^^^^^^^^^^^^^^^^^^^^^^^^^^^^^^^^^^^^^^^^^^
  File "<frozen importlib._bootstrap>", line 1387, in _gcd_import
  File "<frozen importlib._bootstrap>", line 1360, in _find_and_load
  File "<frozen importlib._bootstrap>", line 1310, in _find_and_load_unlocked
  File "<frozen importlib._bootstrap>", line 488, in _call_with_frames_removed
  File "<frozen importlib._bootstrap>", line 1387, in _gcd_import
  File "<frozen importlib._bootstrap>", line 1360, in _find_and_load
  File "<frozen importlib._bootstrap>", line 1324, in _find_and_load_unlocked
ModuleNotFoundError: No module named 'apps.abstract'

During handling of the above exception, another exception occurred:

Traceback (most recent call last):
  File "D:\Azamat\projects\back-end\learning\байэл\baia_messanger\venv\Lib\site-packages\django\core\handlers\exception.py", line 55, in inner
    response = get_response(request)
               ^^^^^^^^^^^^^^^^^^^^^
  File "D:\Azamat\projects\back-end\learning\байэл\baia_messanger\venv\Lib\site-packages\django\core\handlers\base.py", line 197, in _get_response
    response = wrapped_callback(request, *callback_args, **callback_kwargs)
               ^^^^^^^^^^^^^^^^^^^^^^^^^^^^^^^^^^^^^^^^^^^^^^^^^^^^^^^^^^^^
  File "D:\Azamat\projects\back-end\learning\байэл\baia_messanger\venv\Lib\site-packages\django\views\decorators\csrf.py", line 65, in _view_wrapper
    return view_func(request, *args, **kwargs)
           ^^^^^^^^^^^^^^^^^^^^^^^^^^^^^^^^^^^
  File "D:\Azamat\projects\back-end\learning\байэл\baia_messanger\venv\Lib\site-packages\django\views\generic\base.py", line 104, in view
    return self.dispatch(request, *args, **kwargs)
           ^^^^^^^^^^^^^^^^^^^^^^^^^^^^^^^^^^^^^^^
  File "D:\Azamat\projects\back-end\learning\байэл\baia_messanger\venv\Lib\site-packages\rest_framework\views.py", line 509, in dispatch
    response = self.handle_exception(exc)
               ^^^^^^^^^^^^^^^^^^^^^^^^^^
  File "D:\Azamat\projects\back-end\learning\байэл\baia_messanger\venv\Lib\site-packages\rest_framework\views.py", line 463, in handle_exception
    exception_handler = self.get_exception_handler()
                        ^^^^^^^^^^^^^^^^^^^^^^^^^^^^
  File "D:\Azamat\projects\back-end\learning\байэл\baia_messanger\venv\Lib\site-packages\rest_framework\views.py", line 298, in get_exception_handler
    return self.settings.EXCEPTION_HANDLER
           ^^^^^^^^^^^^^^^^^^^^^^^^^^^^^^^
  File "D:\Azamat\projects\back-end\learning\байэл\baia_messanger\venv\Lib\site-packages\rest_framework\settings.py", line 227, in __getattr__
    val = perform_import(val, attr)
          ^^^^^^^^^^^^^^^^^^^^^^^^^
  File "D:\Azamat\projects\back-end\learning\байэл\baia_messanger\venv\Lib\site-packages\rest_framework\settings.py", line 168, in perform_import
    return import_from_string(val, setting_name)
           ^^^^^^^^^^^^^^^^^^^^^^^^^^^^^^^^^^^^^
  File "D:\Azamat\projects\back-end\learning\байэл\baia_messanger\venv\Lib\site-packages\rest_framework\settings.py", line 182, in import_from_string
    raise ImportError(msg)
ImportError: Could not import 'apps.abstract.exceptions.custom_exception_handler' for API setting 'EXCEPTION_HANDLER'. ModuleNotFoundError: No module named 'apps.abstract'.
ERROR 2024-11-29 15:12:11,451 basehttp 20384 18228 "PUT /api/user/me/ HTTP/1.1" 500 25434
ERROR 2024-11-29 15:13:10,433 log 20384 18228 Internal Server Error: /api/user/me/
Traceback (most recent call last):
  File "D:\Azamat\projects\back-end\learning\байэл\baia_messanger\venv\Lib\site-packages\django\core\handlers\exception.py", line 55, in inner
    response = get_response(request)
               ^^^^^^^^^^^^^^^^^^^^^
  File "D:\Azamat\projects\back-end\learning\байэл\baia_messanger\venv\Lib\site-packages\django\core\handlers\base.py", line 197, in _get_response
    response = wrapped_callback(request, *callback_args, **callback_kwargs)
               ^^^^^^^^^^^^^^^^^^^^^^^^^^^^^^^^^^^^^^^^^^^^^^^^^^^^^^^^^^^^
  File "D:\Azamat\projects\back-end\learning\байэл\baia_messanger\venv\Lib\site-packages\django\views\decorators\csrf.py", line 65, in _view_wrapper
    return view_func(request, *args, **kwargs)
           ^^^^^^^^^^^^^^^^^^^^^^^^^^^^^^^^^^^
  File "D:\Azamat\projects\back-end\learning\байэл\baia_messanger\venv\Lib\site-packages\django\views\generic\base.py", line 104, in view
    return self.dispatch(request, *args, **kwargs)
           ^^^^^^^^^^^^^^^^^^^^^^^^^^^^^^^^^^^^^^^
  File "D:\Azamat\projects\back-end\learning\байэл\baia_messanger\venv\Lib\site-packages\rest_framework\views.py", line 509, in dispatch
    response = self.handle_exception(exc)
               ^^^^^^^^^^^^^^^^^^^^^^^^^^
  File "D:\Azamat\projects\back-end\learning\байэл\baia_messanger\venv\Lib\site-packages\rest_framework\views.py", line 469, in handle_exception
    self.raise_uncaught_exception(exc)
  File "D:\Azamat\projects\back-end\learning\байэл\baia_messanger\venv\Lib\site-packages\rest_framework\views.py", line 480, in raise_uncaught_exception
    raise exc
  File "D:\Azamat\projects\back-end\learning\байэл\baia_messanger\venv\Lib\site-packages\rest_framework\views.py", line 506, in dispatch
    response = handler(request, *args, **kwargs)
               ^^^^^^^^^^^^^^^^^^^^^^^^^^^^^^^^^
  File "D:\Azamat\projects\back-end\learning\байэл\baia_messanger\venv\Lib\site-packages\rest_framework\generics.py", line 262, in patch
    return self.partial_update(request, *args, **kwargs)
           ^^^^^^^^^^^^^^^^^^^^^^^^^^^^^^^^^^^^^^^^^^^^^
  File "D:\Azamat\projects\back-end\learning\байэл\baia_messanger\venv\Lib\site-packages\rest_framework\mixins.py", line 82, in partial_update
    return self.update(request, *args, **kwargs)
           ^^^^^^^^^^^^^^^^^^^^^^^^^^^^^^^^^^^^^
  File "D:\Azamat\projects\back-end\learning\байэл\baia_messanger\venv\Lib\site-packages\rest_framework\mixins.py", line 65, in update
    instance = self.get_object()
               ^^^^^^^^^^^^^^^^^
  File "D:\Azamat\projects\back-end\learning\байэл\baia_messanger\venv\Lib\site-packages\rest_framework\generics.py", line 87, in get_object
    queryset = self.filter_queryset(self.get_queryset())
                                    ^^^^^^^^^^^^^^^^^^^
  File "D:\Azamat\projects\back-end\learning\байэл\baia_messanger\venv\Lib\site-packages\rest_framework\generics.py", line 67, in get_queryset
    assert self.queryset is not None, (
           ^^^^^^^^^^^^^^^^^^^^^^^^^
AssertionError: 'UserMeView' should either include a `queryset` attribute, or override the `get_queryset()` method.
ERROR 2024-11-29 15:13:10,437 basehttp 20384 18228 "PATCH /api/user/me/ HTTP/1.1" 500 22939
ERROR 2024-11-29 15:14:08,333 log 20384 18228 Internal Server Error: /api/user/me/
Traceback (most recent call last):
  File "D:\Azamat\projects\back-end\learning\байэл\baia_messanger\venv\Lib\site-packages\django\core\handlers\exception.py", line 55, in inner
    response = get_response(request)
               ^^^^^^^^^^^^^^^^^^^^^
  File "D:\Azamat\projects\back-end\learning\байэл\baia_messanger\venv\Lib\site-packages\django\core\handlers\base.py", line 197, in _get_response
    response = wrapped_callback(request, *callback_args, **callback_kwargs)
               ^^^^^^^^^^^^^^^^^^^^^^^^^^^^^^^^^^^^^^^^^^^^^^^^^^^^^^^^^^^^
  File "D:\Azamat\projects\back-end\learning\байэл\baia_messanger\venv\Lib\site-packages\django\views\decorators\csrf.py", line 65, in _view_wrapper
    return view_func(request, *args, **kwargs)
           ^^^^^^^^^^^^^^^^^^^^^^^^^^^^^^^^^^^
  File "D:\Azamat\projects\back-end\learning\байэл\baia_messanger\venv\Lib\site-packages\django\views\generic\base.py", line 104, in view
    return self.dispatch(request, *args, **kwargs)
           ^^^^^^^^^^^^^^^^^^^^^^^^^^^^^^^^^^^^^^^
  File "D:\Azamat\projects\back-end\learning\байэл\baia_messanger\venv\Lib\site-packages\rest_framework\views.py", line 509, in dispatch
    response = self.handle_exception(exc)
               ^^^^^^^^^^^^^^^^^^^^^^^^^^
  File "D:\Azamat\projects\back-end\learning\байэл\baia_messanger\venv\Lib\site-packages\rest_framework\views.py", line 469, in handle_exception
    self.raise_uncaught_exception(exc)
  File "D:\Azamat\projects\back-end\learning\байэл\baia_messanger\venv\Lib\site-packages\rest_framework\views.py", line 480, in raise_uncaught_exception
    raise exc
  File "D:\Azamat\projects\back-end\learning\байэл\baia_messanger\venv\Lib\site-packages\rest_framework\views.py", line 506, in dispatch
    response = handler(request, *args, **kwargs)
               ^^^^^^^^^^^^^^^^^^^^^^^^^^^^^^^^^
  File "D:\Azamat\projects\back-end\learning\байэл\baia_messanger\venv\Lib\site-packages\rest_framework\generics.py", line 262, in patch
    return self.partial_update(request, *args, **kwargs)
           ^^^^^^^^^^^^^^^^^^^^^^^^^^^^^^^^^^^^^^^^^^^^^
  File "D:\Azamat\projects\back-end\learning\байэл\baia_messanger\venv\Lib\site-packages\rest_framework\mixins.py", line 82, in partial_update
    return self.update(request, *args, **kwargs)
           ^^^^^^^^^^^^^^^^^^^^^^^^^^^^^^^^^^^^^
  File "D:\Azamat\projects\back-end\learning\байэл\baia_messanger\venv\Lib\site-packages\rest_framework\mixins.py", line 65, in update
    instance = self.get_object()
               ^^^^^^^^^^^^^^^^^
  File "D:\Azamat\projects\back-end\learning\байэл\baia_messanger\venv\Lib\site-packages\rest_framework\generics.py", line 87, in get_object
    queryset = self.filter_queryset(self.get_queryset())
                                    ^^^^^^^^^^^^^^^^^^^
  File "D:\Azamat\projects\back-end\learning\байэл\baia_messanger\venv\Lib\site-packages\rest_framework\generics.py", line 67, in get_queryset
    assert self.queryset is not None, (
           ^^^^^^^^^^^^^^^^^^^^^^^^^
AssertionError: 'UserMeView' should either include a `queryset` attribute, or override the `get_queryset()` method.
ERROR 2024-11-29 15:14:08,337 basehttp 20384 18228 "PATCH /api/user/me/ HTTP/1.1" 500 22939
ERROR 2024-11-29 15:14:08,761 log 20384 18228 Internal Server Error: /api/user/me/
Traceback (most recent call last):
  File "D:\Azamat\projects\back-end\learning\байэл\baia_messanger\venv\Lib\site-packages\django\core\handlers\exception.py", line 55, in inner
    response = get_response(request)
               ^^^^^^^^^^^^^^^^^^^^^
  File "D:\Azamat\projects\back-end\learning\байэл\baia_messanger\venv\Lib\site-packages\django\core\handlers\base.py", line 197, in _get_response
    response = wrapped_callback(request, *callback_args, **callback_kwargs)
               ^^^^^^^^^^^^^^^^^^^^^^^^^^^^^^^^^^^^^^^^^^^^^^^^^^^^^^^^^^^^
  File "D:\Azamat\projects\back-end\learning\байэл\baia_messanger\venv\Lib\site-packages\django\views\decorators\csrf.py", line 65, in _view_wrapper
    return view_func(request, *args, **kwargs)
           ^^^^^^^^^^^^^^^^^^^^^^^^^^^^^^^^^^^
  File "D:\Azamat\projects\back-end\learning\байэл\baia_messanger\venv\Lib\site-packages\django\views\generic\base.py", line 104, in view
    return self.dispatch(request, *args, **kwargs)
           ^^^^^^^^^^^^^^^^^^^^^^^^^^^^^^^^^^^^^^^
  File "D:\Azamat\projects\back-end\learning\байэл\baia_messanger\venv\Lib\site-packages\rest_framework\views.py", line 509, in dispatch
    response = self.handle_exception(exc)
               ^^^^^^^^^^^^^^^^^^^^^^^^^^
  File "D:\Azamat\projects\back-end\learning\байэл\baia_messanger\venv\Lib\site-packages\rest_framework\views.py", line 469, in handle_exception
    self.raise_uncaught_exception(exc)
  File "D:\Azamat\projects\back-end\learning\байэл\baia_messanger\venv\Lib\site-packages\rest_framework\views.py", line 480, in raise_uncaught_exception
    raise exc
  File "D:\Azamat\projects\back-end\learning\байэл\baia_messanger\venv\Lib\site-packages\rest_framework\views.py", line 506, in dispatch
    response = handler(request, *args, **kwargs)
               ^^^^^^^^^^^^^^^^^^^^^^^^^^^^^^^^^
  File "D:\Azamat\projects\back-end\learning\байэл\baia_messanger\venv\Lib\site-packages\rest_framework\generics.py", line 262, in patch
    return self.partial_update(request, *args, **kwargs)
           ^^^^^^^^^^^^^^^^^^^^^^^^^^^^^^^^^^^^^^^^^^^^^
  File "D:\Azamat\projects\back-end\learning\байэл\baia_messanger\venv\Lib\site-packages\rest_framework\mixins.py", line 82, in partial_update
    return self.update(request, *args, **kwargs)
           ^^^^^^^^^^^^^^^^^^^^^^^^^^^^^^^^^^^^^
  File "D:\Azamat\projects\back-end\learning\байэл\baia_messanger\venv\Lib\site-packages\rest_framework\mixins.py", line 65, in update
    instance = self.get_object()
               ^^^^^^^^^^^^^^^^^
  File "D:\Azamat\projects\back-end\learning\байэл\baia_messanger\venv\Lib\site-packages\rest_framework\generics.py", line 87, in get_object
    queryset = self.filter_queryset(self.get_queryset())
                                    ^^^^^^^^^^^^^^^^^^^
  File "D:\Azamat\projects\back-end\learning\байэл\baia_messanger\venv\Lib\site-packages\rest_framework\generics.py", line 67, in get_queryset
    assert self.queryset is not None, (
           ^^^^^^^^^^^^^^^^^^^^^^^^^
AssertionError: 'UserMeView' should either include a `queryset` attribute, or override the `get_queryset()` method.
ERROR 2024-11-29 15:14:08,765 basehttp 20384 18228 "PATCH /api/user/me/ HTTP/1.1" 500 22939
ERROR 2024-11-29 15:14:57,811 log 19900 15968 Internal Server Error: /api/user/me/
Traceback (most recent call last):
  File "D:\Azamat\projects\back-end\learning\байэл\baia_messanger\venv\Lib\site-packages\django\core\handlers\exception.py", line 55, in inner
    response = get_response(request)
               ^^^^^^^^^^^^^^^^^^^^^
  File "D:\Azamat\projects\back-end\learning\байэл\baia_messanger\venv\Lib\site-packages\django\core\handlers\base.py", line 197, in _get_response
    response = wrapped_callback(request, *callback_args, **callback_kwargs)
               ^^^^^^^^^^^^^^^^^^^^^^^^^^^^^^^^^^^^^^^^^^^^^^^^^^^^^^^^^^^^
  File "D:\Azamat\projects\back-end\learning\байэл\baia_messanger\venv\Lib\site-packages\django\views\decorators\csrf.py", line 65, in _view_wrapper
    return view_func(request, *args, **kwargs)
           ^^^^^^^^^^^^^^^^^^^^^^^^^^^^^^^^^^^
  File "D:\Azamat\projects\back-end\learning\байэл\baia_messanger\venv\Lib\site-packages\django\views\generic\base.py", line 104, in view
    return self.dispatch(request, *args, **kwargs)
           ^^^^^^^^^^^^^^^^^^^^^^^^^^^^^^^^^^^^^^^
  File "D:\Azamat\projects\back-end\learning\байэл\baia_messanger\venv\Lib\site-packages\rest_framework\views.py", line 509, in dispatch
    response = self.handle_exception(exc)
               ^^^^^^^^^^^^^^^^^^^^^^^^^^
  File "D:\Azamat\projects\back-end\learning\байэл\baia_messanger\venv\Lib\site-packages\rest_framework\views.py", line 469, in handle_exception
    self.raise_uncaught_exception(exc)
  File "D:\Azamat\projects\back-end\learning\байэл\baia_messanger\venv\Lib\site-packages\rest_framework\views.py", line 480, in raise_uncaught_exception
    raise exc
  File "D:\Azamat\projects\back-end\learning\байэл\baia_messanger\venv\Lib\site-packages\rest_framework\views.py", line 506, in dispatch
    response = handler(request, *args, **kwargs)
               ^^^^^^^^^^^^^^^^^^^^^^^^^^^^^^^^^
  File "D:\Azamat\projects\back-end\learning\байэл\baia_messanger\venv\Lib\site-packages\rest_framework\generics.py", line 262, in patch
    return self.partial_update(request, *args, **kwargs)
           ^^^^^^^^^^^^^^^^^^^^^^^^^^^^^^^^^^^^^^^^^^^^^
  File "D:\Azamat\projects\back-end\learning\байэл\baia_messanger\venv\Lib\site-packages\rest_framework\mixins.py", line 82, in partial_update
    return self.update(request, *args, **kwargs)
           ^^^^^^^^^^^^^^^^^^^^^^^^^^^^^^^^^^^^^
  File "D:\Azamat\projects\back-end\learning\байэл\baia_messanger\venv\Lib\site-packages\rest_framework\mixins.py", line 65, in update
    instance = self.get_object()
               ^^^^^^^^^^^^^^^^^
  File "D:\Azamat\projects\back-end\learning\байэл\baia_messanger\venv\Lib\site-packages\rest_framework\generics.py", line 92, in get_object
    assert lookup_url_kwarg in self.kwargs, (
           ^^^^^^^^^^^^^^^^^^^^^^^^^^^^^^^
AssertionError: Expected view UserMeView to be called with a URL keyword argument named "pk". Fix your URL conf, or set the `.lookup_field` attribute on the view correctly.
ERROR 2024-11-29 15:14:57,816 basehttp 19900 15968 "PATCH /api/user/me/ HTTP/1.1" 500 22804
ERROR 2024-11-29 15:23:13,635 log 10672 16984 Internal Server Error: /api/user/me/
Traceback (most recent call last):
  File "D:\Azamat\projects\back-end\learning\байэл\baia_messanger\venv\Lib\site-packages\django\core\handlers\exception.py", line 55, in inner
    response = get_response(request)
               ^^^^^^^^^^^^^^^^^^^^^
  File "D:\Azamat\projects\back-end\learning\байэл\baia_messanger\venv\Lib\site-packages\django\core\handlers\base.py", line 197, in _get_response
    response = wrapped_callback(request, *callback_args, **callback_kwargs)
               ^^^^^^^^^^^^^^^^^^^^^^^^^^^^^^^^^^^^^^^^^^^^^^^^^^^^^^^^^^^^
  File "D:\Azamat\projects\back-end\learning\байэл\baia_messanger\venv\Lib\site-packages\django\views\decorators\csrf.py", line 65, in _view_wrapper
    return view_func(request, *args, **kwargs)
           ^^^^^^^^^^^^^^^^^^^^^^^^^^^^^^^^^^^
  File "D:\Azamat\projects\back-end\learning\байэл\baia_messanger\venv\Lib\site-packages\django\views\generic\base.py", line 104, in view
    return self.dispatch(request, *args, **kwargs)
           ^^^^^^^^^^^^^^^^^^^^^^^^^^^^^^^^^^^^^^^
  File "D:\Azamat\projects\back-end\learning\байэл\baia_messanger\venv\Lib\site-packages\rest_framework\views.py", line 509, in dispatch
    response = self.handle_exception(exc)
               ^^^^^^^^^^^^^^^^^^^^^^^^^^
  File "D:\Azamat\projects\back-end\learning\байэл\baia_messanger\venv\Lib\site-packages\rest_framework\views.py", line 469, in handle_exception
    self.raise_uncaught_exception(exc)
  File "D:\Azamat\projects\back-end\learning\байэл\baia_messanger\venv\Lib\site-packages\rest_framework\views.py", line 480, in raise_uncaught_exception
    raise exc
  File "D:\Azamat\projects\back-end\learning\байэл\baia_messanger\venv\Lib\site-packages\rest_framework\views.py", line 506, in dispatch
    response = handler(request, *args, **kwargs)
               ^^^^^^^^^^^^^^^^^^^^^^^^^^^^^^^^^
  File "D:\Azamat\projects\back-end\learning\байэл\baia_messanger\venv\Lib\site-packages\rest_framework\generics.py", line 262, in patch
    return self.partial_update(request, *args, **kwargs)
           ^^^^^^^^^^^^^^^^^^^^^^^^^^^^^^^^^^^^^^^^^^^^^
  File "D:\Azamat\projects\back-end\learning\байэл\baia_messanger\venv\Lib\site-packages\rest_framework\mixins.py", line 82, in partial_update
    return self.update(request, *args, **kwargs)
           ^^^^^^^^^^^^^^^^^^^^^^^^^^^^^^^^^^^^^
  File "D:\Azamat\projects\back-end\learning\байэл\baia_messanger\venv\Lib\site-packages\rest_framework\mixins.py", line 65, in update
    instance = self.get_object()
               ^^^^^^^^^^^^^^^^^
  File "D:\Azamat\projects\back-end\learning\байэл\baia_messanger\venv\Lib\site-packages\rest_framework\generics.py", line 92, in get_object
    assert lookup_url_kwarg in self.kwargs, (
           ^^^^^^^^^^^^^^^^^^^^^^^^^^^^^^^
AssertionError: Expected view UserMeView to be called with a URL keyword argument named "pk". Fix your URL conf, or set the `.lookup_field` attribute on the view correctly.
ERROR 2024-11-29 15:23:13,640 basehttp 10672 16984 "PATCH /api/user/me/ HTTP/1.1" 500 22804
ERROR 2024-11-29 15:23:15,649 log 10672 16984 Internal Server Error: /api/user/me/
Traceback (most recent call last):
  File "D:\Azamat\projects\back-end\learning\байэл\baia_messanger\venv\Lib\site-packages\django\core\handlers\exception.py", line 55, in inner
    response = get_response(request)
               ^^^^^^^^^^^^^^^^^^^^^
  File "D:\Azamat\projects\back-end\learning\байэл\baia_messanger\venv\Lib\site-packages\django\core\handlers\base.py", line 197, in _get_response
    response = wrapped_callback(request, *callback_args, **callback_kwargs)
               ^^^^^^^^^^^^^^^^^^^^^^^^^^^^^^^^^^^^^^^^^^^^^^^^^^^^^^^^^^^^
  File "D:\Azamat\projects\back-end\learning\байэл\baia_messanger\venv\Lib\site-packages\django\views\decorators\csrf.py", line 65, in _view_wrapper
    return view_func(request, *args, **kwargs)
           ^^^^^^^^^^^^^^^^^^^^^^^^^^^^^^^^^^^
  File "D:\Azamat\projects\back-end\learning\байэл\baia_messanger\venv\Lib\site-packages\django\views\generic\base.py", line 104, in view
    return self.dispatch(request, *args, **kwargs)
           ^^^^^^^^^^^^^^^^^^^^^^^^^^^^^^^^^^^^^^^
  File "D:\Azamat\projects\back-end\learning\байэл\baia_messanger\venv\Lib\site-packages\rest_framework\views.py", line 509, in dispatch
    response = self.handle_exception(exc)
               ^^^^^^^^^^^^^^^^^^^^^^^^^^
  File "D:\Azamat\projects\back-end\learning\байэл\baia_messanger\venv\Lib\site-packages\rest_framework\views.py", line 469, in handle_exception
    self.raise_uncaught_exception(exc)
  File "D:\Azamat\projects\back-end\learning\байэл\baia_messanger\venv\Lib\site-packages\rest_framework\views.py", line 480, in raise_uncaught_exception
    raise exc
  File "D:\Azamat\projects\back-end\learning\байэл\baia_messanger\venv\Lib\site-packages\rest_framework\views.py", line 506, in dispatch
    response = handler(request, *args, **kwargs)
               ^^^^^^^^^^^^^^^^^^^^^^^^^^^^^^^^^
  File "D:\Azamat\projects\back-end\learning\байэл\baia_messanger\venv\Lib\site-packages\rest_framework\generics.py", line 262, in patch
    return self.partial_update(request, *args, **kwargs)
           ^^^^^^^^^^^^^^^^^^^^^^^^^^^^^^^^^^^^^^^^^^^^^
  File "D:\Azamat\projects\back-end\learning\байэл\baia_messanger\venv\Lib\site-packages\rest_framework\mixins.py", line 82, in partial_update
    return self.update(request, *args, **kwargs)
           ^^^^^^^^^^^^^^^^^^^^^^^^^^^^^^^^^^^^^
  File "D:\Azamat\projects\back-end\learning\байэл\baia_messanger\venv\Lib\site-packages\rest_framework\mixins.py", line 65, in update
    instance = self.get_object()
               ^^^^^^^^^^^^^^^^^
  File "D:\Azamat\projects\back-end\learning\байэл\baia_messanger\venv\Lib\site-packages\rest_framework\generics.py", line 92, in get_object
    assert lookup_url_kwarg in self.kwargs, (
           ^^^^^^^^^^^^^^^^^^^^^^^^^^^^^^^
AssertionError: Expected view UserMeView to be called with a URL keyword argument named "pk". Fix your URL conf, or set the `.lookup_field` attribute on the view correctly.
ERROR 2024-11-29 15:23:15,652 basehttp 10672 16984 "PATCH /api/user/me/ HTTP/1.1" 500 22804
ERROR 2024-11-29 15:23:25,909 log 11224 8456 Internal Server Error: /api/user/me/
Traceback (most recent call last):
  File "D:\Azamat\projects\back-end\learning\байэл\baia_messanger\venv\Lib\site-packages\django\core\handlers\exception.py", line 55, in inner
    response = get_response(request)
               ^^^^^^^^^^^^^^^^^^^^^
  File "D:\Azamat\projects\back-end\learning\байэл\baia_messanger\venv\Lib\site-packages\django\core\handlers\base.py", line 197, in _get_response
    response = wrapped_callback(request, *callback_args, **callback_kwargs)
               ^^^^^^^^^^^^^^^^^^^^^^^^^^^^^^^^^^^^^^^^^^^^^^^^^^^^^^^^^^^^
  File "D:\Azamat\projects\back-end\learning\байэл\baia_messanger\venv\Lib\site-packages\django\views\decorators\csrf.py", line 65, in _view_wrapper
    return view_func(request, *args, **kwargs)
           ^^^^^^^^^^^^^^^^^^^^^^^^^^^^^^^^^^^
  File "D:\Azamat\projects\back-end\learning\байэл\baia_messanger\venv\Lib\site-packages\django\views\generic\base.py", line 104, in view
    return self.dispatch(request, *args, **kwargs)
           ^^^^^^^^^^^^^^^^^^^^^^^^^^^^^^^^^^^^^^^
  File "D:\Azamat\projects\back-end\learning\байэл\baia_messanger\venv\Lib\site-packages\rest_framework\views.py", line 509, in dispatch
    response = self.handle_exception(exc)
               ^^^^^^^^^^^^^^^^^^^^^^^^^^
  File "D:\Azamat\projects\back-end\learning\байэл\baia_messanger\venv\Lib\site-packages\rest_framework\views.py", line 469, in handle_exception
    self.raise_uncaught_exception(exc)
  File "D:\Azamat\projects\back-end\learning\байэл\baia_messanger\venv\Lib\site-packages\rest_framework\views.py", line 480, in raise_uncaught_exception
    raise exc
  File "D:\Azamat\projects\back-end\learning\байэл\baia_messanger\venv\Lib\site-packages\rest_framework\views.py", line 506, in dispatch
    response = handler(request, *args, **kwargs)
               ^^^^^^^^^^^^^^^^^^^^^^^^^^^^^^^^^
  File "D:\Azamat\projects\back-end\learning\байэл\baia_messanger\venv\Lib\site-packages\rest_framework\generics.py", line 262, in patch
    return self.partial_update(request, *args, **kwargs)
           ^^^^^^^^^^^^^^^^^^^^^^^^^^^^^^^^^^^^^^^^^^^^^
  File "D:\Azamat\projects\back-end\learning\байэл\baia_messanger\venv\Lib\site-packages\rest_framework\mixins.py", line 82, in partial_update
    return self.update(request, *args, **kwargs)
           ^^^^^^^^^^^^^^^^^^^^^^^^^^^^^^^^^^^^^
  File "D:\Azamat\projects\back-end\learning\байэл\baia_messanger\venv\Lib\site-packages\rest_framework\mixins.py", line 65, in update
    instance = self.get_object()
               ^^^^^^^^^^^^^^^^^
  File "D:\Azamat\projects\back-end\learning\байэл\baia_messanger\venv\Lib\site-packages\rest_framework\generics.py", line 92, in get_object
    assert lookup_url_kwarg in self.kwargs, (
           ^^^^^^^^^^^^^^^^^^^^^^^^^^^^^^^
AssertionError: Expected view UserMeView to be called with a URL keyword argument named "id". Fix your URL conf, or set the `.lookup_field` attribute on the view correctly.
ERROR 2024-11-29 15:23:25,914 basehttp 11224 8456 "PATCH /api/user/me/ HTTP/1.1" 500 22804
ERROR 2024-11-29 15:23:38,353 log 11224 8456 Internal Server Error: /api/user/me/
Traceback (most recent call last):
  File "D:\Azamat\projects\back-end\learning\байэл\baia_messanger\venv\Lib\site-packages\django\core\handlers\exception.py", line 55, in inner
    response = get_response(request)
               ^^^^^^^^^^^^^^^^^^^^^
  File "D:\Azamat\projects\back-end\learning\байэл\baia_messanger\venv\Lib\site-packages\django\core\handlers\base.py", line 197, in _get_response
    response = wrapped_callback(request, *callback_args, **callback_kwargs)
               ^^^^^^^^^^^^^^^^^^^^^^^^^^^^^^^^^^^^^^^^^^^^^^^^^^^^^^^^^^^^
  File "D:\Azamat\projects\back-end\learning\байэл\baia_messanger\venv\Lib\site-packages\django\views\decorators\csrf.py", line 65, in _view_wrapper
    return view_func(request, *args, **kwargs)
           ^^^^^^^^^^^^^^^^^^^^^^^^^^^^^^^^^^^
  File "D:\Azamat\projects\back-end\learning\байэл\baia_messanger\venv\Lib\site-packages\django\views\generic\base.py", line 104, in view
    return self.dispatch(request, *args, **kwargs)
           ^^^^^^^^^^^^^^^^^^^^^^^^^^^^^^^^^^^^^^^
  File "D:\Azamat\projects\back-end\learning\байэл\baia_messanger\venv\Lib\site-packages\rest_framework\views.py", line 509, in dispatch
    response = self.handle_exception(exc)
               ^^^^^^^^^^^^^^^^^^^^^^^^^^
  File "D:\Azamat\projects\back-end\learning\байэл\baia_messanger\venv\Lib\site-packages\rest_framework\views.py", line 469, in handle_exception
    self.raise_uncaught_exception(exc)
  File "D:\Azamat\projects\back-end\learning\байэл\baia_messanger\venv\Lib\site-packages\rest_framework\views.py", line 480, in raise_uncaught_exception
    raise exc
  File "D:\Azamat\projects\back-end\learning\байэл\baia_messanger\venv\Lib\site-packages\rest_framework\views.py", line 506, in dispatch
    response = handler(request, *args, **kwargs)
               ^^^^^^^^^^^^^^^^^^^^^^^^^^^^^^^^^
  File "D:\Azamat\projects\back-end\learning\байэл\baia_messanger\venv\Lib\site-packages\rest_framework\generics.py", line 262, in patch
    return self.partial_update(request, *args, **kwargs)
           ^^^^^^^^^^^^^^^^^^^^^^^^^^^^^^^^^^^^^^^^^^^^^
  File "D:\Azamat\projects\back-end\learning\байэл\baia_messanger\venv\Lib\site-packages\rest_framework\mixins.py", line 82, in partial_update
    return self.update(request, *args, **kwargs)
           ^^^^^^^^^^^^^^^^^^^^^^^^^^^^^^^^^^^^^
  File "D:\Azamat\projects\back-end\learning\байэл\baia_messanger\venv\Lib\site-packages\rest_framework\mixins.py", line 65, in update
    instance = self.get_object()
               ^^^^^^^^^^^^^^^^^
  File "D:\Azamat\projects\back-end\learning\байэл\baia_messanger\venv\Lib\site-packages\rest_framework\generics.py", line 92, in get_object
    assert lookup_url_kwarg in self.kwargs, (
           ^^^^^^^^^^^^^^^^^^^^^^^^^^^^^^^
AssertionError: Expected view UserMeView to be called with a URL keyword argument named "id". Fix your URL conf, or set the `.lookup_field` attribute on the view correctly.
ERROR 2024-11-29 15:23:38,356 basehttp 11224 8456 "PATCH /api/user/me/ HTTP/1.1" 500 22804
ERROR 2024-11-29 15:23:45,116 log 10940 12308 Internal Server Error: /api/user/me/
Traceback (most recent call last):
  File "D:\Azamat\projects\back-end\learning\байэл\baia_messanger\venv\Lib\site-packages\django\core\handlers\exception.py", line 55, in inner
    response = get_response(request)
               ^^^^^^^^^^^^^^^^^^^^^
  File "D:\Azamat\projects\back-end\learning\байэл\baia_messanger\venv\Lib\site-packages\django\core\handlers\base.py", line 197, in _get_response
    response = wrapped_callback(request, *callback_args, **callback_kwargs)
               ^^^^^^^^^^^^^^^^^^^^^^^^^^^^^^^^^^^^^^^^^^^^^^^^^^^^^^^^^^^^
  File "D:\Azamat\projects\back-end\learning\байэл\baia_messanger\venv\Lib\site-packages\django\views\decorators\csrf.py", line 65, in _view_wrapper
    return view_func(request, *args, **kwargs)
           ^^^^^^^^^^^^^^^^^^^^^^^^^^^^^^^^^^^
  File "D:\Azamat\projects\back-end\learning\байэл\baia_messanger\venv\Lib\site-packages\django\views\generic\base.py", line 104, in view
    return self.dispatch(request, *args, **kwargs)
           ^^^^^^^^^^^^^^^^^^^^^^^^^^^^^^^^^^^^^^^
  File "D:\Azamat\projects\back-end\learning\байэл\baia_messanger\venv\Lib\site-packages\rest_framework\views.py", line 509, in dispatch
    response = self.handle_exception(exc)
               ^^^^^^^^^^^^^^^^^^^^^^^^^^
  File "D:\Azamat\projects\back-end\learning\байэл\baia_messanger\venv\Lib\site-packages\rest_framework\views.py", line 469, in handle_exception
    self.raise_uncaught_exception(exc)
  File "D:\Azamat\projects\back-end\learning\байэл\baia_messanger\venv\Lib\site-packages\rest_framework\views.py", line 480, in raise_uncaught_exception
    raise exc
  File "D:\Azamat\projects\back-end\learning\байэл\baia_messanger\venv\Lib\site-packages\rest_framework\views.py", line 506, in dispatch
    response = handler(request, *args, **kwargs)
               ^^^^^^^^^^^^^^^^^^^^^^^^^^^^^^^^^
  File "D:\Azamat\projects\back-end\learning\байэл\baia_messanger\venv\Lib\site-packages\rest_framework\generics.py", line 256, in get
    return self.retrieve(request, *args, **kwargs)
           ^^^^^^^^^^^^^^^^^^^^^^^^^^^^^^^^^^^^^^^
  File "D:\Azamat\projects\back-end\learning\байэл\baia_messanger\venv\Lib\site-packages\rest_framework\mixins.py", line 54, in retrieve
    instance = self.get_object()
               ^^^^^^^^^^^^^^^^^
  File "D:\Azamat\projects\back-end\learning\байэл\baia_messanger\venv\Lib\site-packages\rest_framework\generics.py", line 92, in get_object
    assert lookup_url_kwarg in self.kwargs, (
           ^^^^^^^^^^^^^^^^^^^^^^^^^^^^^^^
AssertionError: Expected view UserMeView to be called with a URL keyword argument named "id". Fix your URL conf, or set the `.lookup_field` attribute on the view correctly.
ERROR 2024-11-29 15:23:45,120 basehttp 10940 12308 "GET /api/user/me/ HTTP/1.1" 500 22496
ERROR 2024-11-29 15:23:55,168 log 10940 12308 Internal Server Error: /api/user/me/
Traceback (most recent call last):
  File "D:\Azamat\projects\back-end\learning\байэл\baia_messanger\venv\Lib\site-packages\django\core\handlers\exception.py", line 55, in inner
    response = get_response(request)
               ^^^^^^^^^^^^^^^^^^^^^
  File "D:\Azamat\projects\back-end\learning\байэл\baia_messanger\venv\Lib\site-packages\django\core\handlers\base.py", line 197, in _get_response
    response = wrapped_callback(request, *callback_args, **callback_kwargs)
               ^^^^^^^^^^^^^^^^^^^^^^^^^^^^^^^^^^^^^^^^^^^^^^^^^^^^^^^^^^^^
  File "D:\Azamat\projects\back-end\learning\байэл\baia_messanger\venv\Lib\site-packages\django\views\decorators\csrf.py", line 65, in _view_wrapper
    return view_func(request, *args, **kwargs)
           ^^^^^^^^^^^^^^^^^^^^^^^^^^^^^^^^^^^
  File "D:\Azamat\projects\back-end\learning\байэл\baia_messanger\venv\Lib\site-packages\django\views\generic\base.py", line 104, in view
    return self.dispatch(request, *args, **kwargs)
           ^^^^^^^^^^^^^^^^^^^^^^^^^^^^^^^^^^^^^^^
  File "D:\Azamat\projects\back-end\learning\байэл\baia_messanger\venv\Lib\site-packages\rest_framework\views.py", line 509, in dispatch
    response = self.handle_exception(exc)
               ^^^^^^^^^^^^^^^^^^^^^^^^^^
  File "D:\Azamat\projects\back-end\learning\байэл\baia_messanger\venv\Lib\site-packages\rest_framework\views.py", line 469, in handle_exception
    self.raise_uncaught_exception(exc)
  File "D:\Azamat\projects\back-end\learning\байэл\baia_messanger\venv\Lib\site-packages\rest_framework\views.py", line 480, in raise_uncaught_exception
    raise exc
  File "D:\Azamat\projects\back-end\learning\байэл\baia_messanger\venv\Lib\site-packages\rest_framework\views.py", line 506, in dispatch
    response = handler(request, *args, **kwargs)
               ^^^^^^^^^^^^^^^^^^^^^^^^^^^^^^^^^
  File "D:\Azamat\projects\back-end\learning\байэл\baia_messanger\venv\Lib\site-packages\rest_framework\generics.py", line 256, in get
    return self.retrieve(request, *args, **kwargs)
           ^^^^^^^^^^^^^^^^^^^^^^^^^^^^^^^^^^^^^^^
  File "D:\Azamat\projects\back-end\learning\байэл\baia_messanger\venv\Lib\site-packages\rest_framework\mixins.py", line 54, in retrieve
    instance = self.get_object()
               ^^^^^^^^^^^^^^^^^
  File "D:\Azamat\projects\back-end\learning\байэл\baia_messanger\venv\Lib\site-packages\rest_framework\generics.py", line 92, in get_object
    assert lookup_url_kwarg in self.kwargs, (
           ^^^^^^^^^^^^^^^^^^^^^^^^^^^^^^^
AssertionError: Expected view UserMeView to be called with a URL keyword argument named "id". Fix your URL conf, or set the `.lookup_field` attribute on the view correctly.
ERROR 2024-11-29 15:23:55,171 basehttp 10940 12308 "GET /api/user/me/ HTTP/1.1" 500 22496
ERROR 2024-11-29 15:23:58,382 log 14592 13980 Internal Server Error: /api/user/me/
Traceback (most recent call last):
  File "D:\Azamat\projects\back-end\learning\байэл\baia_messanger\venv\Lib\site-packages\django\core\handlers\exception.py", line 55, in inner
    response = get_response(request)
               ^^^^^^^^^^^^^^^^^^^^^
  File "D:\Azamat\projects\back-end\learning\байэл\baia_messanger\venv\Lib\site-packages\django\core\handlers\base.py", line 197, in _get_response
    response = wrapped_callback(request, *callback_args, **callback_kwargs)
               ^^^^^^^^^^^^^^^^^^^^^^^^^^^^^^^^^^^^^^^^^^^^^^^^^^^^^^^^^^^^
  File "D:\Azamat\projects\back-end\learning\байэл\baia_messanger\venv\Lib\site-packages\django\views\decorators\csrf.py", line 65, in _view_wrapper
    return view_func(request, *args, **kwargs)
           ^^^^^^^^^^^^^^^^^^^^^^^^^^^^^^^^^^^
  File "D:\Azamat\projects\back-end\learning\байэл\baia_messanger\venv\Lib\site-packages\django\views\generic\base.py", line 104, in view
    return self.dispatch(request, *args, **kwargs)
           ^^^^^^^^^^^^^^^^^^^^^^^^^^^^^^^^^^^^^^^
  File "D:\Azamat\projects\back-end\learning\байэл\baia_messanger\venv\Lib\site-packages\rest_framework\views.py", line 509, in dispatch
    response = self.handle_exception(exc)
               ^^^^^^^^^^^^^^^^^^^^^^^^^^
  File "D:\Azamat\projects\back-end\learning\байэл\baia_messanger\venv\Lib\site-packages\rest_framework\views.py", line 469, in handle_exception
    self.raise_uncaught_exception(exc)
  File "D:\Azamat\projects\back-end\learning\байэл\baia_messanger\venv\Lib\site-packages\rest_framework\views.py", line 480, in raise_uncaught_exception
    raise exc
  File "D:\Azamat\projects\back-end\learning\байэл\baia_messanger\venv\Lib\site-packages\rest_framework\views.py", line 506, in dispatch
    response = handler(request, *args, **kwargs)
               ^^^^^^^^^^^^^^^^^^^^^^^^^^^^^^^^^
  File "D:\Azamat\projects\back-end\learning\байэл\baia_messanger\venv\Lib\site-packages\rest_framework\generics.py", line 256, in get
    return self.retrieve(request, *args, **kwargs)
           ^^^^^^^^^^^^^^^^^^^^^^^^^^^^^^^^^^^^^^^
  File "D:\Azamat\projects\back-end\learning\байэл\baia_messanger\venv\Lib\site-packages\rest_framework\mixins.py", line 54, in retrieve
    instance = self.get_object()
               ^^^^^^^^^^^^^^^^^
  File "D:\Azamat\projects\back-end\learning\байэл\baia_messanger\venv\Lib\site-packages\rest_framework\generics.py", line 92, in get_object
    assert lookup_url_kwarg in self.kwargs, (
           ^^^^^^^^^^^^^^^^^^^^^^^^^^^^^^^
AssertionError: Expected view UserMeView to be called with a URL keyword argument named "pk". Fix your URL conf, or set the `.lookup_field` attribute on the view correctly.
ERROR 2024-11-29 15:23:58,387 basehttp 14592 13980 "GET /api/user/me/ HTTP/1.1" 500 22496
ERROR 2024-11-29 15:23:59,040 log 14592 13980 Internal Server Error: /api/user/me/
Traceback (most recent call last):
  File "D:\Azamat\projects\back-end\learning\байэл\baia_messanger\venv\Lib\site-packages\django\core\handlers\exception.py", line 55, in inner
    response = get_response(request)
               ^^^^^^^^^^^^^^^^^^^^^
  File "D:\Azamat\projects\back-end\learning\байэл\baia_messanger\venv\Lib\site-packages\django\core\handlers\base.py", line 197, in _get_response
    response = wrapped_callback(request, *callback_args, **callback_kwargs)
               ^^^^^^^^^^^^^^^^^^^^^^^^^^^^^^^^^^^^^^^^^^^^^^^^^^^^^^^^^^^^
  File "D:\Azamat\projects\back-end\learning\байэл\baia_messanger\venv\Lib\site-packages\django\views\decorators\csrf.py", line 65, in _view_wrapper
    return view_func(request, *args, **kwargs)
           ^^^^^^^^^^^^^^^^^^^^^^^^^^^^^^^^^^^
  File "D:\Azamat\projects\back-end\learning\байэл\baia_messanger\venv\Lib\site-packages\django\views\generic\base.py", line 104, in view
    return self.dispatch(request, *args, **kwargs)
           ^^^^^^^^^^^^^^^^^^^^^^^^^^^^^^^^^^^^^^^
  File "D:\Azamat\projects\back-end\learning\байэл\baia_messanger\venv\Lib\site-packages\rest_framework\views.py", line 509, in dispatch
    response = self.handle_exception(exc)
               ^^^^^^^^^^^^^^^^^^^^^^^^^^
  File "D:\Azamat\projects\back-end\learning\байэл\baia_messanger\venv\Lib\site-packages\rest_framework\views.py", line 469, in handle_exception
    self.raise_uncaught_exception(exc)
  File "D:\Azamat\projects\back-end\learning\байэл\baia_messanger\venv\Lib\site-packages\rest_framework\views.py", line 480, in raise_uncaught_exception
    raise exc
  File "D:\Azamat\projects\back-end\learning\байэл\baia_messanger\venv\Lib\site-packages\rest_framework\views.py", line 506, in dispatch
    response = handler(request, *args, **kwargs)
               ^^^^^^^^^^^^^^^^^^^^^^^^^^^^^^^^^
  File "D:\Azamat\projects\back-end\learning\байэл\baia_messanger\venv\Lib\site-packages\rest_framework\generics.py", line 256, in get
    return self.retrieve(request, *args, **kwargs)
           ^^^^^^^^^^^^^^^^^^^^^^^^^^^^^^^^^^^^^^^
  File "D:\Azamat\projects\back-end\learning\байэл\baia_messanger\venv\Lib\site-packages\rest_framework\mixins.py", line 54, in retrieve
    instance = self.get_object()
               ^^^^^^^^^^^^^^^^^
  File "D:\Azamat\projects\back-end\learning\байэл\baia_messanger\venv\Lib\site-packages\rest_framework\generics.py", line 92, in get_object
    assert lookup_url_kwarg in self.kwargs, (
           ^^^^^^^^^^^^^^^^^^^^^^^^^^^^^^^
AssertionError: Expected view UserMeView to be called with a URL keyword argument named "pk". Fix your URL conf, or set the `.lookup_field` attribute on the view correctly.
ERROR 2024-11-29 15:23:59,044 basehttp 14592 13980 "GET /api/user/me/ HTTP/1.1" 500 22496
ERROR 2024-11-29 15:23:59,598 log 14592 13980 Internal Server Error: /api/user/me/
Traceback (most recent call last):
  File "D:\Azamat\projects\back-end\learning\байэл\baia_messanger\venv\Lib\site-packages\django\core\handlers\exception.py", line 55, in inner
    response = get_response(request)
               ^^^^^^^^^^^^^^^^^^^^^
  File "D:\Azamat\projects\back-end\learning\байэл\baia_messanger\venv\Lib\site-packages\django\core\handlers\base.py", line 197, in _get_response
    response = wrapped_callback(request, *callback_args, **callback_kwargs)
               ^^^^^^^^^^^^^^^^^^^^^^^^^^^^^^^^^^^^^^^^^^^^^^^^^^^^^^^^^^^^
  File "D:\Azamat\projects\back-end\learning\байэл\baia_messanger\venv\Lib\site-packages\django\views\decorators\csrf.py", line 65, in _view_wrapper
    return view_func(request, *args, **kwargs)
           ^^^^^^^^^^^^^^^^^^^^^^^^^^^^^^^^^^^
  File "D:\Azamat\projects\back-end\learning\байэл\baia_messanger\venv\Lib\site-packages\django\views\generic\base.py", line 104, in view
    return self.dispatch(request, *args, **kwargs)
           ^^^^^^^^^^^^^^^^^^^^^^^^^^^^^^^^^^^^^^^
  File "D:\Azamat\projects\back-end\learning\байэл\baia_messanger\venv\Lib\site-packages\rest_framework\views.py", line 509, in dispatch
    response = self.handle_exception(exc)
               ^^^^^^^^^^^^^^^^^^^^^^^^^^
  File "D:\Azamat\projects\back-end\learning\байэл\baia_messanger\venv\Lib\site-packages\rest_framework\views.py", line 469, in handle_exception
    self.raise_uncaught_exception(exc)
  File "D:\Azamat\projects\back-end\learning\байэл\baia_messanger\venv\Lib\site-packages\rest_framework\views.py", line 480, in raise_uncaught_exception
    raise exc
  File "D:\Azamat\projects\back-end\learning\байэл\baia_messanger\venv\Lib\site-packages\rest_framework\views.py", line 506, in dispatch
    response = handler(request, *args, **kwargs)
               ^^^^^^^^^^^^^^^^^^^^^^^^^^^^^^^^^
  File "D:\Azamat\projects\back-end\learning\байэл\baia_messanger\venv\Lib\site-packages\rest_framework\generics.py", line 256, in get
    return self.retrieve(request, *args, **kwargs)
           ^^^^^^^^^^^^^^^^^^^^^^^^^^^^^^^^^^^^^^^
  File "D:\Azamat\projects\back-end\learning\байэл\baia_messanger\venv\Lib\site-packages\rest_framework\mixins.py", line 54, in retrieve
    instance = self.get_object()
               ^^^^^^^^^^^^^^^^^
  File "D:\Azamat\projects\back-end\learning\байэл\baia_messanger\venv\Lib\site-packages\rest_framework\generics.py", line 92, in get_object
    assert lookup_url_kwarg in self.kwargs, (
           ^^^^^^^^^^^^^^^^^^^^^^^^^^^^^^^
AssertionError: Expected view UserMeView to be called with a URL keyword argument named "pk". Fix your URL conf, or set the `.lookup_field` attribute on the view correctly.
ERROR 2024-11-29 15:23:59,601 basehttp 14592 13980 "GET /api/user/me/ HTTP/1.1" 500 22496
ERROR 2024-11-29 15:24:00,165 log 14592 13980 Internal Server Error: /api/user/me/
Traceback (most recent call last):
  File "D:\Azamat\projects\back-end\learning\байэл\baia_messanger\venv\Lib\site-packages\django\core\handlers\exception.py", line 55, in inner
    response = get_response(request)
               ^^^^^^^^^^^^^^^^^^^^^
  File "D:\Azamat\projects\back-end\learning\байэл\baia_messanger\venv\Lib\site-packages\django\core\handlers\base.py", line 197, in _get_response
    response = wrapped_callback(request, *callback_args, **callback_kwargs)
               ^^^^^^^^^^^^^^^^^^^^^^^^^^^^^^^^^^^^^^^^^^^^^^^^^^^^^^^^^^^^
  File "D:\Azamat\projects\back-end\learning\байэл\baia_messanger\venv\Lib\site-packages\django\views\decorators\csrf.py", line 65, in _view_wrapper
    return view_func(request, *args, **kwargs)
           ^^^^^^^^^^^^^^^^^^^^^^^^^^^^^^^^^^^
  File "D:\Azamat\projects\back-end\learning\байэл\baia_messanger\venv\Lib\site-packages\django\views\generic\base.py", line 104, in view
    return self.dispatch(request, *args, **kwargs)
           ^^^^^^^^^^^^^^^^^^^^^^^^^^^^^^^^^^^^^^^
  File "D:\Azamat\projects\back-end\learning\байэл\baia_messanger\venv\Lib\site-packages\rest_framework\views.py", line 509, in dispatch
    response = self.handle_exception(exc)
               ^^^^^^^^^^^^^^^^^^^^^^^^^^
  File "D:\Azamat\projects\back-end\learning\байэл\baia_messanger\venv\Lib\site-packages\rest_framework\views.py", line 469, in handle_exception
    self.raise_uncaught_exception(exc)
  File "D:\Azamat\projects\back-end\learning\байэл\baia_messanger\venv\Lib\site-packages\rest_framework\views.py", line 480, in raise_uncaught_exception
    raise exc
  File "D:\Azamat\projects\back-end\learning\байэл\baia_messanger\venv\Lib\site-packages\rest_framework\views.py", line 506, in dispatch
    response = handler(request, *args, **kwargs)
               ^^^^^^^^^^^^^^^^^^^^^^^^^^^^^^^^^
  File "D:\Azamat\projects\back-end\learning\байэл\baia_messanger\venv\Lib\site-packages\rest_framework\generics.py", line 256, in get
    return self.retrieve(request, *args, **kwargs)
           ^^^^^^^^^^^^^^^^^^^^^^^^^^^^^^^^^^^^^^^
  File "D:\Azamat\projects\back-end\learning\байэл\baia_messanger\venv\Lib\site-packages\rest_framework\mixins.py", line 54, in retrieve
    instance = self.get_object()
               ^^^^^^^^^^^^^^^^^
  File "D:\Azamat\projects\back-end\learning\байэл\baia_messanger\venv\Lib\site-packages\rest_framework\generics.py", line 92, in get_object
    assert lookup_url_kwarg in self.kwargs, (
           ^^^^^^^^^^^^^^^^^^^^^^^^^^^^^^^
AssertionError: Expected view UserMeView to be called with a URL keyword argument named "pk". Fix your URL conf, or set the `.lookup_field` attribute on the view correctly.
ERROR 2024-11-29 15:24:00,169 basehttp 14592 13980 "GET /api/user/me/ HTTP/1.1" 500 22496
ERROR 2024-11-29 15:24:05,635 log 14592 13980 Internal Server Error: /api/user/me/
Traceback (most recent call last):
  File "D:\Azamat\projects\back-end\learning\байэл\baia_messanger\venv\Lib\site-packages\django\core\handlers\exception.py", line 55, in inner
    response = get_response(request)
               ^^^^^^^^^^^^^^^^^^^^^
  File "D:\Azamat\projects\back-end\learning\байэл\baia_messanger\venv\Lib\site-packages\django\core\handlers\base.py", line 197, in _get_response
    response = wrapped_callback(request, *callback_args, **callback_kwargs)
               ^^^^^^^^^^^^^^^^^^^^^^^^^^^^^^^^^^^^^^^^^^^^^^^^^^^^^^^^^^^^
  File "D:\Azamat\projects\back-end\learning\байэл\baia_messanger\venv\Lib\site-packages\django\views\decorators\csrf.py", line 65, in _view_wrapper
    return view_func(request, *args, **kwargs)
           ^^^^^^^^^^^^^^^^^^^^^^^^^^^^^^^^^^^
  File "D:\Azamat\projects\back-end\learning\байэл\baia_messanger\venv\Lib\site-packages\django\views\generic\base.py", line 104, in view
    return self.dispatch(request, *args, **kwargs)
           ^^^^^^^^^^^^^^^^^^^^^^^^^^^^^^^^^^^^^^^
  File "D:\Azamat\projects\back-end\learning\байэл\baia_messanger\venv\Lib\site-packages\rest_framework\views.py", line 509, in dispatch
    response = self.handle_exception(exc)
               ^^^^^^^^^^^^^^^^^^^^^^^^^^
  File "D:\Azamat\projects\back-end\learning\байэл\baia_messanger\venv\Lib\site-packages\rest_framework\views.py", line 469, in handle_exception
    self.raise_uncaught_exception(exc)
  File "D:\Azamat\projects\back-end\learning\байэл\baia_messanger\venv\Lib\site-packages\rest_framework\views.py", line 480, in raise_uncaught_exception
    raise exc
  File "D:\Azamat\projects\back-end\learning\байэл\baia_messanger\venv\Lib\site-packages\rest_framework\views.py", line 506, in dispatch
    response = handler(request, *args, **kwargs)
               ^^^^^^^^^^^^^^^^^^^^^^^^^^^^^^^^^
  File "D:\Azamat\projects\back-end\learning\байэл\baia_messanger\venv\Lib\site-packages\rest_framework\generics.py", line 256, in get
    return self.retrieve(request, *args, **kwargs)
           ^^^^^^^^^^^^^^^^^^^^^^^^^^^^^^^^^^^^^^^
  File "D:\Azamat\projects\back-end\learning\байэл\baia_messanger\venv\Lib\site-packages\rest_framework\mixins.py", line 54, in retrieve
    instance = self.get_object()
               ^^^^^^^^^^^^^^^^^
  File "D:\Azamat\projects\back-end\learning\байэл\baia_messanger\venv\Lib\site-packages\rest_framework\generics.py", line 92, in get_object
    assert lookup_url_kwarg in self.kwargs, (
           ^^^^^^^^^^^^^^^^^^^^^^^^^^^^^^^
AssertionError: Expected view UserMeView to be called with a URL keyword argument named "pk". Fix your URL conf, or set the `.lookup_field` attribute on the view correctly.
ERROR 2024-11-29 15:24:05,638 basehttp 14592 13980 "GET /api/user/me/ HTTP/1.1" 500 22496
ERROR 2024-11-29 15:24:36,237 log 16416 3680 Internal Server Error: /api/user/me/
Traceback (most recent call last):
  File "D:\Azamat\projects\back-end\learning\байэл\baia_messanger\venv\Lib\site-packages\django\core\handlers\exception.py", line 55, in inner
    response = get_response(request)
               ^^^^^^^^^^^^^^^^^^^^^
  File "D:\Azamat\projects\back-end\learning\байэл\baia_messanger\venv\Lib\site-packages\django\core\handlers\base.py", line 197, in _get_response
    response = wrapped_callback(request, *callback_args, **callback_kwargs)
               ^^^^^^^^^^^^^^^^^^^^^^^^^^^^^^^^^^^^^^^^^^^^^^^^^^^^^^^^^^^^
  File "D:\Azamat\projects\back-end\learning\байэл\baia_messanger\venv\Lib\site-packages\django\views\decorators\csrf.py", line 65, in _view_wrapper
    return view_func(request, *args, **kwargs)
           ^^^^^^^^^^^^^^^^^^^^^^^^^^^^^^^^^^^
  File "D:\Azamat\projects\back-end\learning\байэл\baia_messanger\venv\Lib\site-packages\django\views\generic\base.py", line 104, in view
    return self.dispatch(request, *args, **kwargs)
           ^^^^^^^^^^^^^^^^^^^^^^^^^^^^^^^^^^^^^^^
  File "D:\Azamat\projects\back-end\learning\байэл\baia_messanger\venv\Lib\site-packages\rest_framework\views.py", line 509, in dispatch
    response = self.handle_exception(exc)
               ^^^^^^^^^^^^^^^^^^^^^^^^^^
  File "D:\Azamat\projects\back-end\learning\байэл\baia_messanger\venv\Lib\site-packages\rest_framework\views.py", line 469, in handle_exception
    self.raise_uncaught_exception(exc)
  File "D:\Azamat\projects\back-end\learning\байэл\baia_messanger\venv\Lib\site-packages\rest_framework\views.py", line 480, in raise_uncaught_exception
    raise exc
  File "D:\Azamat\projects\back-end\learning\байэл\baia_messanger\venv\Lib\site-packages\rest_framework\views.py", line 506, in dispatch
    response = handler(request, *args, **kwargs)
               ^^^^^^^^^^^^^^^^^^^^^^^^^^^^^^^^^
  File "D:\Azamat\projects\back-end\learning\байэл\baia_messanger\venv\Lib\site-packages\rest_framework\generics.py", line 262, in patch
    return self.partial_update(request, *args, **kwargs)
           ^^^^^^^^^^^^^^^^^^^^^^^^^^^^^^^^^^^^^^^^^^^^^
  File "D:\Azamat\projects\back-end\learning\байэл\baia_messanger\venv\Lib\site-packages\rest_framework\mixins.py", line 82, in partial_update
    return self.update(request, *args, **kwargs)
           ^^^^^^^^^^^^^^^^^^^^^^^^^^^^^^^^^^^^^
  File "D:\Azamat\projects\back-end\learning\байэл\baia_messanger\venv\Lib\site-packages\rest_framework\mixins.py", line 65, in update
    instance = self.get_object()
               ^^^^^^^^^^^^^^^^^
  File "D:\Azamat\projects\back-end\learning\байэл\baia_messanger\venv\Lib\site-packages\rest_framework\generics.py", line 92, in get_object
    assert lookup_url_kwarg in self.kwargs, (
           ^^^^^^^^^^^^^^^^^^^^^^^^^^^^^^^
AssertionError: Expected view UserMeView to be called with a URL keyword argument named "pk". Fix your URL conf, or set the `.lookup_field` attribute on the view correctly.
ERROR 2024-11-29 15:24:36,242 basehttp 16416 3680 "PATCH /api/user/me/ HTTP/1.1" 500 22804
ERROR 2024-11-29 15:26:32,237 log 15448 5640 Internal Server Error: /api/user/me/
Traceback (most recent call last):
  File "D:\Azamat\projects\back-end\learning\байэл\baia_messanger\venv\Lib\site-packages\django\core\handlers\exception.py", line 55, in inner
    response = get_response(request)
               ^^^^^^^^^^^^^^^^^^^^^
  File "D:\Azamat\projects\back-end\learning\байэл\baia_messanger\venv\Lib\site-packages\django\core\handlers\base.py", line 197, in _get_response
    response = wrapped_callback(request, *callback_args, **callback_kwargs)
               ^^^^^^^^^^^^^^^^^^^^^^^^^^^^^^^^^^^^^^^^^^^^^^^^^^^^^^^^^^^^
  File "D:\Azamat\projects\back-end\learning\байэл\baia_messanger\venv\Lib\site-packages\django\views\decorators\csrf.py", line 65, in _view_wrapper
    return view_func(request, *args, **kwargs)
           ^^^^^^^^^^^^^^^^^^^^^^^^^^^^^^^^^^^
  File "D:\Azamat\projects\back-end\learning\байэл\baia_messanger\venv\Lib\site-packages\django\views\generic\base.py", line 104, in view
    return self.dispatch(request, *args, **kwargs)
           ^^^^^^^^^^^^^^^^^^^^^^^^^^^^^^^^^^^^^^^
  File "D:\Azamat\projects\back-end\learning\байэл\baia_messanger\venv\Lib\site-packages\rest_framework\views.py", line 509, in dispatch
    response = self.handle_exception(exc)
               ^^^^^^^^^^^^^^^^^^^^^^^^^^
  File "D:\Azamat\projects\back-end\learning\байэл\baia_messanger\venv\Lib\site-packages\rest_framework\views.py", line 469, in handle_exception
    self.raise_uncaught_exception(exc)
  File "D:\Azamat\projects\back-end\learning\байэл\baia_messanger\venv\Lib\site-packages\rest_framework\views.py", line 480, in raise_uncaught_exception
    raise exc
  File "D:\Azamat\projects\back-end\learning\байэл\baia_messanger\venv\Lib\site-packages\rest_framework\views.py", line 506, in dispatch
    response = handler(request, *args, **kwargs)
               ^^^^^^^^^^^^^^^^^^^^^^^^^^^^^^^^^
  File "D:\Azamat\projects\back-end\learning\байэл\baia_messanger\venv\Lib\site-packages\rest_framework\generics.py", line 262, in patch
    return self.partial_update(request, *args, **kwargs)
           ^^^^^^^^^^^^^^^^^^^^^^^^^^^^^^^^^^^^^^^^^^^^^
  File "D:\Azamat\projects\back-end\learning\байэл\baia_messanger\venv\Lib\site-packages\rest_framework\mixins.py", line 82, in partial_update
    return self.update(request, *args, **kwargs)
           ^^^^^^^^^^^^^^^^^^^^^^^^^^^^^^^^^^^^^
  File "D:\Azamat\projects\back-end\learning\байэл\baia_messanger\venv\Lib\site-packages\rest_framework\mixins.py", line 65, in update
    instance = self.get_object()
               ^^^^^^^^^^^^^^^^^
  File "D:\Azamat\projects\back-end\learning\байэл\baia_messanger\venv\Lib\site-packages\rest_framework\generics.py", line 92, in get_object
    assert lookup_url_kwarg in self.kwargs, (
           ^^^^^^^^^^^^^^^^^^^^^^^^^^^^^^^
AssertionError: Expected view UserMeView to be called with a URL keyword argument named "pk". Fix your URL conf, or set the `.lookup_field` attribute on the view correctly.
ERROR 2024-11-29 15:26:32,243 basehttp 15448 5640 "PATCH /api/user/me/ HTTP/1.1" 500 22804
ERROR 2024-11-29 16:28:14,768 log 5568 14136 Internal Server Error: /api/user/regisration/
Traceback (most recent call last):
  File "D:\Azamat\projects\back-end\learning\байэл\baia_messanger\venv\Lib\site-packages\django\db\backends\utils.py", line 105, in _execute
    return self.cursor.execute(sql, params)
           ^^^^^^^^^^^^^^^^^^^^^^^^^^^^^^^^
  File "D:\Azamat\projects\back-end\learning\байэл\baia_messanger\venv\Lib\site-packages\django\db\backends\sqlite3\base.py", line 354, in execute
    return super().execute(query, params)
           ^^^^^^^^^^^^^^^^^^^^^^^^^^^^^^
sqlite3.IntegrityError: NOT NULL constraint failed: user_user.name

The above exception was the direct cause of the following exception:

Traceback (most recent call last):
  File "D:\Azamat\projects\back-end\learning\байэл\baia_messanger\venv\Lib\site-packages\django\core\handlers\exception.py", line 55, in inner
    response = get_response(request)
               ^^^^^^^^^^^^^^^^^^^^^
  File "D:\Azamat\projects\back-end\learning\байэл\baia_messanger\venv\Lib\site-packages\django\core\handlers\base.py", line 197, in _get_response
    response = wrapped_callback(request, *callback_args, **callback_kwargs)
               ^^^^^^^^^^^^^^^^^^^^^^^^^^^^^^^^^^^^^^^^^^^^^^^^^^^^^^^^^^^^
  File "D:\Azamat\projects\back-end\learning\байэл\baia_messanger\venv\Lib\site-packages\django\views\decorators\csrf.py", line 65, in _view_wrapper
    return view_func(request, *args, **kwargs)
           ^^^^^^^^^^^^^^^^^^^^^^^^^^^^^^^^^^^
  File "D:\Azamat\projects\back-end\learning\байэл\baia_messanger\venv\Lib\site-packages\django\views\generic\base.py", line 104, in view
    return self.dispatch(request, *args, **kwargs)
           ^^^^^^^^^^^^^^^^^^^^^^^^^^^^^^^^^^^^^^^
  File "D:\Azamat\projects\back-end\learning\байэл\baia_messanger\venv\Lib\site-packages\rest_framework\views.py", line 509, in dispatch
    response = self.handle_exception(exc)
               ^^^^^^^^^^^^^^^^^^^^^^^^^^
  File "D:\Azamat\projects\back-end\learning\байэл\baia_messanger\venv\Lib\site-packages\rest_framework\views.py", line 469, in handle_exception
    self.raise_uncaught_exception(exc)
  File "D:\Azamat\projects\back-end\learning\байэл\baia_messanger\venv\Lib\site-packages\rest_framework\views.py", line 480, in raise_uncaught_exception
    raise exc
  File "D:\Azamat\projects\back-end\learning\байэл\baia_messanger\venv\Lib\site-packages\rest_framework\views.py", line 506, in dispatch
    response = handler(request, *args, **kwargs)
               ^^^^^^^^^^^^^^^^^^^^^^^^^^^^^^^^^
  File "D:\Azamat\projects\back-end\learning\байэл\baia_messanger\api\v1\views\views.py", line 39, in post
    serializer.save()
  File "D:\Azamat\projects\back-end\learning\байэл\baia_messanger\venv\Lib\site-packages\rest_framework\serializers.py", line 208, in save
    self.instance = self.create(validated_data)
                    ^^^^^^^^^^^^^^^^^^^^^^^^^^^
  File "D:\Azamat\projects\back-end\learning\байэл\baia_messanger\api\v1\serializers\user.py", line 32, in create
    user = User.objects.create_user(**validated_data)
           ^^^^^^^^^^^^^^^^^^^^^^^^^^^^^^^^^^^^^^^^^^
  File "D:\Azamat\projects\back-end\learning\байэл\baia_messanger\venv\Lib\site-packages\django\contrib\auth\models.py", line 162, in create_user
    return self._create_user(username, email, password, **extra_fields)
           ^^^^^^^^^^^^^^^^^^^^^^^^^^^^^^^^^^^^^^^^^^^^^^^^^^^^^^^^^^^^
  File "D:\Azamat\projects\back-end\learning\байэл\baia_messanger\venv\Lib\site-packages\django\contrib\auth\models.py", line 156, in _create_user
    user.save(using=self._db)
  File "D:\Azamat\projects\back-end\learning\байэл\baia_messanger\venv\Lib\site-packages\django\contrib\auth\base_user.py", line 62, in save
    super().save(*args, **kwargs)
  File "D:\Azamat\projects\back-end\learning\байэл\baia_messanger\venv\Lib\site-packages\django\db\models\base.py", line 891, in save
    self.save_base(
  File "D:\Azamat\projects\back-end\learning\байэл\baia_messanger\venv\Lib\site-packages\django\db\models\base.py", line 997, in save_base
    updated = self._save_table(
              ^^^^^^^^^^^^^^^^^
  File "D:\Azamat\projects\back-end\learning\байэл\baia_messanger\venv\Lib\site-packages\django\db\models\base.py", line 1160, in _save_table
    results = self._do_insert(
              ^^^^^^^^^^^^^^^^
  File "D:\Azamat\projects\back-end\learning\байэл\baia_messanger\venv\Lib\site-packages\django\db\models\base.py", line 1201, in _do_insert
    return manager._insert(
           ^^^^^^^^^^^^^^^^
  File "D:\Azamat\projects\back-end\learning\байэл\baia_messanger\venv\Lib\site-packages\django\db\models\manager.py", line 87, in manager_method
    return getattr(self.get_queryset(), name)(*args, **kwargs)
           ^^^^^^^^^^^^^^^^^^^^^^^^^^^^^^^^^^^^^^^^^^^^^^^^^^^
  File "D:\Azamat\projects\back-end\learning\байэл\baia_messanger\venv\Lib\site-packages\django\db\models\query.py", line 1847, in _insert
    return query.get_compiler(using=using).execute_sql(returning_fields)
           ^^^^^^^^^^^^^^^^^^^^^^^^^^^^^^^^^^^^^^^^^^^^^^^^^^^^^^^^^^^^^
  File "D:\Azamat\projects\back-end\learning\байэл\baia_messanger\venv\Lib\site-packages\django\db\models\sql\compiler.py", line 1836, in execute_sql
    cursor.execute(sql, params)
  File "D:\Azamat\projects\back-end\learning\байэл\baia_messanger\venv\Lib\site-packages\django\db\backends\utils.py", line 122, in execute
    return super().execute(sql, params)
           ^^^^^^^^^^^^^^^^^^^^^^^^^^^^
  File "D:\Azamat\projects\back-end\learning\байэл\baia_messanger\venv\Lib\site-packages\django\db\backends\utils.py", line 79, in execute
    return self._execute_with_wrappers(
           ^^^^^^^^^^^^^^^^^^^^^^^^^^^^
  File "D:\Azamat\projects\back-end\learning\байэл\baia_messanger\venv\Lib\site-packages\django\db\backends\utils.py", line 92, in _execute_with_wrappers
    return executor(sql, params, many, context)
           ^^^^^^^^^^^^^^^^^^^^^^^^^^^^^^^^^^^^
  File "D:\Azamat\projects\back-end\learning\байэл\baia_messanger\venv\Lib\site-packages\django\db\backends\utils.py", line 100, in _execute
    with self.db.wrap_database_errors:
  File "D:\Azamat\projects\back-end\learning\байэл\baia_messanger\venv\Lib\site-packages\django\db\utils.py", line 91, in __exit__
    raise dj_exc_value.with_traceback(traceback) from exc_value
  File "D:\Azamat\projects\back-end\learning\байэл\baia_messanger\venv\Lib\site-packages\django\db\backends\utils.py", line 105, in _execute
    return self.cursor.execute(sql, params)
           ^^^^^^^^^^^^^^^^^^^^^^^^^^^^^^^^
  File "D:\Azamat\projects\back-end\learning\байэл\baia_messanger\venv\Lib\site-packages\django\db\backends\sqlite3\base.py", line 354, in execute
    return super().execute(query, params)
           ^^^^^^^^^^^^^^^^^^^^^^^^^^^^^^
django.db.utils.IntegrityError: NOT NULL constraint failed: user_user.name
ERROR 2024-11-29 16:28:14,779 basehttp 5568 14136 "POST /api/user/regisration/ HTTP/1.1" 500 26775
ERROR 2024-11-29 16:33:38,617 log 7688 9140 Internal Server Error: /api/user/update/
Traceback (most recent call last):
  File "D:\Azamat\projects\back-end\learning\байэл\baia_messanger\venv\Lib\site-packages\rest_framework\request.py", line 421, in __getattr__
    return getattr(_request, attr)
           ^^^^^^^^^^^^^^^^^^^^^^^
AttributeError: 'WSGIRequest' object has no attribute 'username'

During handling of the above exception, another exception occurred:

Traceback (most recent call last):
  File "D:\Azamat\projects\back-end\learning\байэл\baia_messanger\venv\Lib\site-packages\rest_framework\fields.py", line 437, in get_attribute
    return get_attribute(instance, self.source_attrs)
           ^^^^^^^^^^^^^^^^^^^^^^^^^^^^^^^^^^^^^^^^^^
  File "D:\Azamat\projects\back-end\learning\байэл\baia_messanger\venv\Lib\site-packages\rest_framework\fields.py", line 104, in get_attribute
    instance = getattr(instance, attr)
               ^^^^^^^^^^^^^^^^^^^^^^^
  File "D:\Azamat\projects\back-end\learning\байэл\baia_messanger\venv\Lib\site-packages\rest_framework\request.py", line 423, in __getattr__
    return self.__getattribute__(attr)
           ^^^^^^^^^^^^^^^^^^^^^^^^^^^
AttributeError: 'Request' object has no attribute 'username'

During handling of the above exception, another exception occurred:

Traceback (most recent call last):
  File "D:\Azamat\projects\back-end\learning\байэл\baia_messanger\venv\Lib\site-packages\django\core\handlers\exception.py", line 55, in inner
    response = get_response(request)
               ^^^^^^^^^^^^^^^^^^^^^
  File "D:\Azamat\projects\back-end\learning\байэл\baia_messanger\venv\Lib\site-packages\django\core\handlers\base.py", line 197, in _get_response
    response = wrapped_callback(request, *callback_args, **callback_kwargs)
               ^^^^^^^^^^^^^^^^^^^^^^^^^^^^^^^^^^^^^^^^^^^^^^^^^^^^^^^^^^^^
  File "D:\Azamat\projects\back-end\learning\байэл\baia_messanger\venv\Lib\site-packages\django\views\decorators\csrf.py", line 65, in _view_wrapper
    return view_func(request, *args, **kwargs)
           ^^^^^^^^^^^^^^^^^^^^^^^^^^^^^^^^^^^
  File "D:\Azamat\projects\back-end\learning\байэл\baia_messanger\venv\Lib\site-packages\django\views\generic\base.py", line 104, in view
    return self.dispatch(request, *args, **kwargs)
           ^^^^^^^^^^^^^^^^^^^^^^^^^^^^^^^^^^^^^^^
  File "D:\Azamat\projects\back-end\learning\байэл\baia_messanger\venv\Lib\site-packages\rest_framework\views.py", line 509, in dispatch
    response = self.handle_exception(exc)
               ^^^^^^^^^^^^^^^^^^^^^^^^^^
  File "D:\Azamat\projects\back-end\learning\байэл\baia_messanger\venv\Lib\site-packages\rest_framework\views.py", line 469, in handle_exception
    self.raise_uncaught_exception(exc)
  File "D:\Azamat\projects\back-end\learning\байэл\baia_messanger\venv\Lib\site-packages\rest_framework\views.py", line 480, in raise_uncaught_exception
    raise exc
  File "D:\Azamat\projects\back-end\learning\байэл\baia_messanger\venv\Lib\site-packages\rest_framework\views.py", line 506, in dispatch
    response = handler(request, *args, **kwargs)
               ^^^^^^^^^^^^^^^^^^^^^^^^^^^^^^^^^
  File "D:\Azamat\projects\back-end\learning\байэл\baia_messanger\api\v1\views\views.py", line 24, in get
    return Response(serializer.data, status=status.HTTP_200_OK)
                    ^^^^^^^^^^^^^^^
  File "D:\Azamat\projects\back-end\learning\байэл\baia_messanger\venv\Lib\site-packages\rest_framework\serializers.py", line 571, in data
    ret = super().data
          ^^^^^^^^^^^^
  File "D:\Azamat\projects\back-end\learning\байэл\baia_messanger\venv\Lib\site-packages\rest_framework\serializers.py", line 249, in data
    self._data = self.to_representation(self.instance)
                 ^^^^^^^^^^^^^^^^^^^^^^^^^^^^^^^^^^^^^
  File "D:\Azamat\projects\back-end\learning\байэл\baia_messanger\venv\Lib\site-packages\rest_framework\serializers.py", line 525, in to_representation
    attribute = field.get_attribute(instance)
                ^^^^^^^^^^^^^^^^^^^^^^^^^^^^^
  File "D:\Azamat\projects\back-end\learning\байэл\baia_messanger\venv\Lib\site-packages\rest_framework\fields.py", line 470, in get_attribute
    raise type(exc)(msg)
AttributeError: Got AttributeError when attempting to get a value for field `username` on serializer `UserMeSerializer`.
The serializer field might be named incorrectly and not match any attribute or key on the `Request` instance.
Original exception text was: 'Request' object has no attribute 'username'.
ERROR 2024-11-29 16:33:38,626 basehttp 7688 9140 "GET /api/user/update/ HTTP/1.1" 500 24359
ERROR 2024-11-29 16:34:14,902 log 10808 13744 Internal Server Error: /api/user/update/
Traceback (most recent call last):
  File "D:\Azamat\projects\back-end\learning\байэл\baia_messanger\venv\Lib\site-packages\rest_framework\request.py", line 421, in __getattr__
    return getattr(_request, attr)
           ^^^^^^^^^^^^^^^^^^^^^^^
AttributeError: 'WSGIRequest' object has no attribute 'username'

During handling of the above exception, another exception occurred:

Traceback (most recent call last):
  File "D:\Azamat\projects\back-end\learning\байэл\baia_messanger\venv\Lib\site-packages\rest_framework\fields.py", line 437, in get_attribute
    return get_attribute(instance, self.source_attrs)
           ^^^^^^^^^^^^^^^^^^^^^^^^^^^^^^^^^^^^^^^^^^
  File "D:\Azamat\projects\back-end\learning\байэл\baia_messanger\venv\Lib\site-packages\rest_framework\fields.py", line 104, in get_attribute
    instance = getattr(instance, attr)
               ^^^^^^^^^^^^^^^^^^^^^^^
  File "D:\Azamat\projects\back-end\learning\байэл\baia_messanger\venv\Lib\site-packages\rest_framework\request.py", line 423, in __getattr__
    return self.__getattribute__(attr)
           ^^^^^^^^^^^^^^^^^^^^^^^^^^^
AttributeError: 'Request' object has no attribute 'username'

During handling of the above exception, another exception occurred:

Traceback (most recent call last):
  File "D:\Azamat\projects\back-end\learning\байэл\baia_messanger\venv\Lib\site-packages\django\core\handlers\exception.py", line 55, in inner
    response = get_response(request)
               ^^^^^^^^^^^^^^^^^^^^^
  File "D:\Azamat\projects\back-end\learning\байэл\baia_messanger\venv\Lib\site-packages\django\core\handlers\base.py", line 197, in _get_response
    response = wrapped_callback(request, *callback_args, **callback_kwargs)
               ^^^^^^^^^^^^^^^^^^^^^^^^^^^^^^^^^^^^^^^^^^^^^^^^^^^^^^^^^^^^
  File "D:\Azamat\projects\back-end\learning\байэл\baia_messanger\venv\Lib\site-packages\django\views\decorators\csrf.py", line 65, in _view_wrapper
    return view_func(request, *args, **kwargs)
           ^^^^^^^^^^^^^^^^^^^^^^^^^^^^^^^^^^^
  File "D:\Azamat\projects\back-end\learning\байэл\baia_messanger\venv\Lib\site-packages\django\views\generic\base.py", line 104, in view
    return self.dispatch(request, *args, **kwargs)
           ^^^^^^^^^^^^^^^^^^^^^^^^^^^^^^^^^^^^^^^
  File "D:\Azamat\projects\back-end\learning\байэл\baia_messanger\venv\Lib\site-packages\rest_framework\views.py", line 509, in dispatch
    response = self.handle_exception(exc)
               ^^^^^^^^^^^^^^^^^^^^^^^^^^
  File "D:\Azamat\projects\back-end\learning\байэл\baia_messanger\venv\Lib\site-packages\rest_framework\views.py", line 469, in handle_exception
    self.raise_uncaught_exception(exc)
  File "D:\Azamat\projects\back-end\learning\байэл\baia_messanger\venv\Lib\site-packages\rest_framework\views.py", line 480, in raise_uncaught_exception
    raise exc
  File "D:\Azamat\projects\back-end\learning\байэл\baia_messanger\venv\Lib\site-packages\rest_framework\views.py", line 506, in dispatch
    response = handler(request, *args, **kwargs)
               ^^^^^^^^^^^^^^^^^^^^^^^^^^^^^^^^^
  File "D:\Azamat\projects\back-end\learning\байэл\baia_messanger\api\v1\views\views.py", line 24, in put
    return Response(serializer.data, status=status.HTTP_200_OK)
                    ^^^^^^^^^^^^^^^
  File "D:\Azamat\projects\back-end\learning\байэл\baia_messanger\venv\Lib\site-packages\rest_framework\serializers.py", line 571, in data
    ret = super().data
          ^^^^^^^^^^^^
  File "D:\Azamat\projects\back-end\learning\байэл\baia_messanger\venv\Lib\site-packages\rest_framework\serializers.py", line 249, in data
    self._data = self.to_representation(self.instance)
                 ^^^^^^^^^^^^^^^^^^^^^^^^^^^^^^^^^^^^^
  File "D:\Azamat\projects\back-end\learning\байэл\baia_messanger\venv\Lib\site-packages\rest_framework\serializers.py", line 525, in to_representation
    attribute = field.get_attribute(instance)
                ^^^^^^^^^^^^^^^^^^^^^^^^^^^^^
  File "D:\Azamat\projects\back-end\learning\байэл\baia_messanger\venv\Lib\site-packages\rest_framework\fields.py", line 470, in get_attribute
    raise type(exc)(msg)
AttributeError: Got AttributeError when attempting to get a value for field `username` on serializer `UserMeSerializer`.
The serializer field might be named incorrectly and not match any attribute or key on the `Request` instance.
Original exception text was: 'Request' object has no attribute 'username'.
ERROR 2024-11-29 16:34:14,911 basehttp 10808 13744 "PUT /api/user/update/ HTTP/1.1" 500 24406
ERROR 2024-11-29 16:41:35,935 log 10808 15860 Internal Server Error: /api/user/update/
Traceback (most recent call last):
  File "D:\Azamat\projects\back-end\learning\байэл\baia_messanger\venv\Lib\site-packages\rest_framework\request.py", line 421, in __getattr__
    return getattr(_request, attr)
           ^^^^^^^^^^^^^^^^^^^^^^^
AttributeError: 'WSGIRequest' object has no attribute 'username'

During handling of the above exception, another exception occurred:

Traceback (most recent call last):
  File "D:\Azamat\projects\back-end\learning\байэл\baia_messanger\venv\Lib\site-packages\rest_framework\fields.py", line 437, in get_attribute
    return get_attribute(instance, self.source_attrs)
           ^^^^^^^^^^^^^^^^^^^^^^^^^^^^^^^^^^^^^^^^^^
  File "D:\Azamat\projects\back-end\learning\байэл\baia_messanger\venv\Lib\site-packages\rest_framework\fields.py", line 104, in get_attribute
    instance = getattr(instance, attr)
               ^^^^^^^^^^^^^^^^^^^^^^^
  File "D:\Azamat\projects\back-end\learning\байэл\baia_messanger\venv\Lib\site-packages\rest_framework\request.py", line 423, in __getattr__
    return self.__getattribute__(attr)
           ^^^^^^^^^^^^^^^^^^^^^^^^^^^
AttributeError: 'Request' object has no attribute 'username'

During handling of the above exception, another exception occurred:

Traceback (most recent call last):
  File "D:\Azamat\projects\back-end\learning\байэл\baia_messanger\venv\Lib\site-packages\django\core\handlers\exception.py", line 55, in inner
    response = get_response(request)
               ^^^^^^^^^^^^^^^^^^^^^
  File "D:\Azamat\projects\back-end\learning\байэл\baia_messanger\venv\Lib\site-packages\django\core\handlers\base.py", line 197, in _get_response
    response = wrapped_callback(request, *callback_args, **callback_kwargs)
               ^^^^^^^^^^^^^^^^^^^^^^^^^^^^^^^^^^^^^^^^^^^^^^^^^^^^^^^^^^^^
  File "D:\Azamat\projects\back-end\learning\байэл\baia_messanger\venv\Lib\site-packages\django\views\decorators\csrf.py", line 65, in _view_wrapper
    return view_func(request, *args, **kwargs)
           ^^^^^^^^^^^^^^^^^^^^^^^^^^^^^^^^^^^
  File "D:\Azamat\projects\back-end\learning\байэл\baia_messanger\venv\Lib\site-packages\django\views\generic\base.py", line 104, in view
    return self.dispatch(request, *args, **kwargs)
           ^^^^^^^^^^^^^^^^^^^^^^^^^^^^^^^^^^^^^^^
  File "D:\Azamat\projects\back-end\learning\байэл\baia_messanger\venv\Lib\site-packages\rest_framework\views.py", line 509, in dispatch
    response = self.handle_exception(exc)
               ^^^^^^^^^^^^^^^^^^^^^^^^^^
  File "D:\Azamat\projects\back-end\learning\байэл\baia_messanger\venv\Lib\site-packages\rest_framework\views.py", line 469, in handle_exception
    self.raise_uncaught_exception(exc)
  File "D:\Azamat\projects\back-end\learning\байэл\baia_messanger\venv\Lib\site-packages\rest_framework\views.py", line 480, in raise_uncaught_exception
    raise exc
  File "D:\Azamat\projects\back-end\learning\байэл\baia_messanger\venv\Lib\site-packages\rest_framework\views.py", line 506, in dispatch
    response = handler(request, *args, **kwargs)
               ^^^^^^^^^^^^^^^^^^^^^^^^^^^^^^^^^
  File "D:\Azamat\projects\back-end\learning\байэл\baia_messanger\api\v1\views\views.py", line 24, in put
    return Response(serializer.data, status=status.HTTP_200_OK)
                    ^^^^^^^^^^^^^^^
  File "D:\Azamat\projects\back-end\learning\байэл\baia_messanger\venv\Lib\site-packages\rest_framework\serializers.py", line 571, in data
    ret = super().data
          ^^^^^^^^^^^^
  File "D:\Azamat\projects\back-end\learning\байэл\baia_messanger\venv\Lib\site-packages\rest_framework\serializers.py", line 249, in data
    self._data = self.to_representation(self.instance)
                 ^^^^^^^^^^^^^^^^^^^^^^^^^^^^^^^^^^^^^
  File "D:\Azamat\projects\back-end\learning\байэл\baia_messanger\venv\Lib\site-packages\rest_framework\serializers.py", line 525, in to_representation
    attribute = field.get_attribute(instance)
                ^^^^^^^^^^^^^^^^^^^^^^^^^^^^^
  File "D:\Azamat\projects\back-end\learning\байэл\baia_messanger\venv\Lib\site-packages\rest_framework\fields.py", line 470, in get_attribute
    raise type(exc)(msg)
AttributeError: Got AttributeError when attempting to get a value for field `username` on serializer `UserMeSerializer`.
The serializer field might be named incorrectly and not match any attribute or key on the `Request` instance.
Original exception text was: 'Request' object has no attribute 'username'.
ERROR 2024-11-29 16:41:35,942 basehttp 10808 15860 "PUT /api/user/update/ HTTP/1.1" 500 24406
ERROR 2024-11-29 16:51:34,374 log 1572 18728 Internal Server Error: /api/user/update/
Traceback (most recent call last):
  File "D:\Azamat\projects\back-end\learning\байэл\baia_messanger\venv\Lib\site-packages\rest_framework\request.py", line 421, in __getattr__
    return getattr(_request, attr)
           ^^^^^^^^^^^^^^^^^^^^^^^
AttributeError: 'WSGIRequest' object has no attribute 'username'

During handling of the above exception, another exception occurred:

Traceback (most recent call last):
  File "D:\Azamat\projects\back-end\learning\байэл\baia_messanger\venv\Lib\site-packages\rest_framework\fields.py", line 437, in get_attribute
    return get_attribute(instance, self.source_attrs)
           ^^^^^^^^^^^^^^^^^^^^^^^^^^^^^^^^^^^^^^^^^^
  File "D:\Azamat\projects\back-end\learning\байэл\baia_messanger\venv\Lib\site-packages\rest_framework\fields.py", line 104, in get_attribute
    instance = getattr(instance, attr)
               ^^^^^^^^^^^^^^^^^^^^^^^
  File "D:\Azamat\projects\back-end\learning\байэл\baia_messanger\venv\Lib\site-packages\rest_framework\request.py", line 423, in __getattr__
    return self.__getattribute__(attr)
           ^^^^^^^^^^^^^^^^^^^^^^^^^^^
AttributeError: 'Request' object has no attribute 'username'

During handling of the above exception, another exception occurred:

Traceback (most recent call last):
  File "D:\Azamat\projects\back-end\learning\байэл\baia_messanger\venv\Lib\site-packages\django\core\handlers\exception.py", line 55, in inner
    response = get_response(request)
               ^^^^^^^^^^^^^^^^^^^^^
  File "D:\Azamat\projects\back-end\learning\байэл\baia_messanger\venv\Lib\site-packages\django\core\handlers\base.py", line 197, in _get_response
    response = wrapped_callback(request, *callback_args, **callback_kwargs)
               ^^^^^^^^^^^^^^^^^^^^^^^^^^^^^^^^^^^^^^^^^^^^^^^^^^^^^^^^^^^^
  File "D:\Azamat\projects\back-end\learning\байэл\baia_messanger\venv\Lib\site-packages\django\views\decorators\csrf.py", line 65, in _view_wrapper
    return view_func(request, *args, **kwargs)
           ^^^^^^^^^^^^^^^^^^^^^^^^^^^^^^^^^^^
  File "D:\Azamat\projects\back-end\learning\байэл\baia_messanger\venv\Lib\site-packages\django\views\generic\base.py", line 104, in view
    return self.dispatch(request, *args, **kwargs)
           ^^^^^^^^^^^^^^^^^^^^^^^^^^^^^^^^^^^^^^^
  File "D:\Azamat\projects\back-end\learning\байэл\baia_messanger\venv\Lib\site-packages\rest_framework\views.py", line 509, in dispatch
    response = self.handle_exception(exc)
               ^^^^^^^^^^^^^^^^^^^^^^^^^^
  File "D:\Azamat\projects\back-end\learning\байэл\baia_messanger\venv\Lib\site-packages\rest_framework\views.py", line 469, in handle_exception
    self.raise_uncaught_exception(exc)
  File "D:\Azamat\projects\back-end\learning\байэл\baia_messanger\venv\Lib\site-packages\rest_framework\views.py", line 480, in raise_uncaught_exception
    raise exc
  File "D:\Azamat\projects\back-end\learning\байэл\baia_messanger\venv\Lib\site-packages\rest_framework\views.py", line 506, in dispatch
    response = handler(request, *args, **kwargs)
               ^^^^^^^^^^^^^^^^^^^^^^^^^^^^^^^^^
  File "D:\Azamat\projects\back-end\learning\байэл\baia_messanger\api\v1\views\views.py", line 24, in put
    return Response(serializer.data, status=status.HTTP_200_OK)
                    ^^^^^^^^^^^^^^^
  File "D:\Azamat\projects\back-end\learning\байэл\baia_messanger\venv\Lib\site-packages\rest_framework\serializers.py", line 571, in data
    ret = super().data
          ^^^^^^^^^^^^
  File "D:\Azamat\projects\back-end\learning\байэл\baia_messanger\venv\Lib\site-packages\rest_framework\serializers.py", line 249, in data
    self._data = self.to_representation(self.instance)
                 ^^^^^^^^^^^^^^^^^^^^^^^^^^^^^^^^^^^^^
  File "D:\Azamat\projects\back-end\learning\байэл\baia_messanger\venv\Lib\site-packages\rest_framework\serializers.py", line 525, in to_representation
    attribute = field.get_attribute(instance)
                ^^^^^^^^^^^^^^^^^^^^^^^^^^^^^
  File "D:\Azamat\projects\back-end\learning\байэл\baia_messanger\venv\Lib\site-packages\rest_framework\fields.py", line 470, in get_attribute
    raise type(exc)(msg)
AttributeError: Got AttributeError when attempting to get a value for field `username` on serializer `UserMeSerializer`.
The serializer field might be named incorrectly and not match any attribute or key on the `Request` instance.
Original exception text was: 'Request' object has no attribute 'username'.
ERROR 2024-11-29 16:51:34,384 basehttp 1572 18728 "PUT /api/user/update/ HTTP/1.1" 500 24406
ERROR 2024-11-29 16:53:03,968 log 16848 20396 Internal Server Error: /api/user/update/
Traceback (most recent call last):
  File "D:\Azamat\projects\back-end\learning\байэл\baia_messanger\venv\Lib\site-packages\django\core\handlers\exception.py", line 55, in inner
    response = get_response(request)
               ^^^^^^^^^^^^^^^^^^^^^
  File "D:\Azamat\projects\back-end\learning\байэл\baia_messanger\venv\Lib\site-packages\django\core\handlers\base.py", line 197, in _get_response
    response = wrapped_callback(request, *callback_args, **callback_kwargs)
               ^^^^^^^^^^^^^^^^^^^^^^^^^^^^^^^^^^^^^^^^^^^^^^^^^^^^^^^^^^^^
  File "D:\Azamat\projects\back-end\learning\байэл\baia_messanger\venv\Lib\site-packages\django\views\decorators\csrf.py", line 65, in _view_wrapper
    return view_func(request, *args, **kwargs)
           ^^^^^^^^^^^^^^^^^^^^^^^^^^^^^^^^^^^
  File "D:\Azamat\projects\back-end\learning\байэл\baia_messanger\venv\Lib\site-packages\django\views\generic\base.py", line 104, in view
    return self.dispatch(request, *args, **kwargs)
           ^^^^^^^^^^^^^^^^^^^^^^^^^^^^^^^^^^^^^^^
  File "D:\Azamat\projects\back-end\learning\байэл\baia_messanger\venv\Lib\site-packages\rest_framework\views.py", line 509, in dispatch
    response = self.handle_exception(exc)
               ^^^^^^^^^^^^^^^^^^^^^^^^^^
  File "D:\Azamat\projects\back-end\learning\байэл\baia_messanger\venv\Lib\site-packages\rest_framework\views.py", line 469, in handle_exception
    self.raise_uncaught_exception(exc)
  File "D:\Azamat\projects\back-end\learning\байэл\baia_messanger\venv\Lib\site-packages\rest_framework\views.py", line 480, in raise_uncaught_exception
    raise exc
  File "D:\Azamat\projects\back-end\learning\байэл\baia_messanger\venv\Lib\site-packages\rest_framework\views.py", line 506, in dispatch
    response = handler(request, *args, **kwargs)
               ^^^^^^^^^^^^^^^^^^^^^^^^^^^^^^^^^
  File "D:\Azamat\projects\back-end\learning\байэл\baia_messanger\api\v1\views\views.py", line 23, in patch
    user = self.get_object()
           ^^^^^^^^^^^^^^^^^
  File "D:\Azamat\projects\back-end\learning\байэл\baia_messanger\venv\Lib\site-packages\rest_framework\generics.py", line 87, in get_object
    queryset = self.filter_queryset(self.get_queryset())
                                    ^^^^^^^^^^^^^^^^^^^
  File "D:\Azamat\projects\back-end\learning\байэл\baia_messanger\venv\Lib\site-packages\rest_framework\generics.py", line 67, in get_queryset
    assert self.queryset is not None, (
           ^^^^^^^^^^^^^^^^^^^^^^^^^
AssertionError: 'UserUpdateView' should either include a `queryset` attribute, or override the `get_queryset()` method.
ERROR 2024-11-29 16:53:03,973 basehttp 16848 20396 "PATCH /api/user/update/ HTTP/1.1" 500 22433
ERROR 2024-11-29 16:53:34,507 log 1316 9828 Internal Server Error: /api/user/update/
Traceback (most recent call last):
  File "D:\Azamat\projects\back-end\learning\байэл\baia_messanger\venv\Lib\site-packages\django\core\handlers\exception.py", line 55, in inner
    response = get_response(request)
               ^^^^^^^^^^^^^^^^^^^^^
  File "D:\Azamat\projects\back-end\learning\байэл\baia_messanger\venv\Lib\site-packages\django\core\handlers\base.py", line 197, in _get_response
    response = wrapped_callback(request, *callback_args, **callback_kwargs)
               ^^^^^^^^^^^^^^^^^^^^^^^^^^^^^^^^^^^^^^^^^^^^^^^^^^^^^^^^^^^^
  File "D:\Azamat\projects\back-end\learning\байэл\baia_messanger\venv\Lib\site-packages\django\views\decorators\csrf.py", line 65, in _view_wrapper
    return view_func(request, *args, **kwargs)
           ^^^^^^^^^^^^^^^^^^^^^^^^^^^^^^^^^^^
  File "D:\Azamat\projects\back-end\learning\байэл\baia_messanger\venv\Lib\site-packages\django\views\generic\base.py", line 104, in view
    return self.dispatch(request, *args, **kwargs)
           ^^^^^^^^^^^^^^^^^^^^^^^^^^^^^^^^^^^^^^^
  File "D:\Azamat\projects\back-end\learning\байэл\baia_messanger\venv\Lib\site-packages\rest_framework\views.py", line 509, in dispatch
    response = self.handle_exception(exc)
               ^^^^^^^^^^^^^^^^^^^^^^^^^^
  File "D:\Azamat\projects\back-end\learning\байэл\baia_messanger\venv\Lib\site-packages\rest_framework\views.py", line 469, in handle_exception
    self.raise_uncaught_exception(exc)
  File "D:\Azamat\projects\back-end\learning\байэл\baia_messanger\venv\Lib\site-packages\rest_framework\views.py", line 480, in raise_uncaught_exception
    raise exc
  File "D:\Azamat\projects\back-end\learning\байэл\baia_messanger\venv\Lib\site-packages\rest_framework\views.py", line 506, in dispatch
    response = handler(request, *args, **kwargs)
               ^^^^^^^^^^^^^^^^^^^^^^^^^^^^^^^^^
  File "D:\Azamat\projects\back-end\learning\байэл\baia_messanger\venv\Lib\site-packages\rest_framework\generics.py", line 212, in get
    return self.retrieve(request, *args, **kwargs)
           ^^^^^^^^^^^^^^^^^^^^^^^^^^^^^^^^^^^^^^^
  File "D:\Azamat\projects\back-end\learning\байэл\baia_messanger\venv\Lib\site-packages\rest_framework\mixins.py", line 54, in retrieve
    instance = self.get_object()
               ^^^^^^^^^^^^^^^^^
  File "D:\Azamat\projects\back-end\learning\байэл\baia_messanger\venv\Lib\site-packages\rest_framework\generics.py", line 87, in get_object
    queryset = self.filter_queryset(self.get_queryset())
                                    ^^^^^^^^^^^^^^^^^^^
  File "D:\Azamat\projects\back-end\learning\байэл\baia_messanger\venv\Lib\site-packages\rest_framework\generics.py", line 67, in get_queryset
    assert self.queryset is not None, (
           ^^^^^^^^^^^^^^^^^^^^^^^^^
AssertionError: 'UserUpdateView' should either include a `queryset` attribute, or override the `get_queryset()` method.
ERROR 2024-11-29 16:53:34,511 basehttp 1316 9828 "GET /api/user/update/ HTTP/1.1" 500 22661
ERROR 2024-11-29 16:53:53,312 log 1316 9828 Internal Server Error: /api/user/update/
Traceback (most recent call last):
  File "D:\Azamat\projects\back-end\learning\байэл\baia_messanger\venv\Lib\site-packages\django\core\handlers\exception.py", line 55, in inner
    response = get_response(request)
               ^^^^^^^^^^^^^^^^^^^^^
  File "D:\Azamat\projects\back-end\learning\байэл\baia_messanger\venv\Lib\site-packages\django\core\handlers\base.py", line 197, in _get_response
    response = wrapped_callback(request, *callback_args, **callback_kwargs)
               ^^^^^^^^^^^^^^^^^^^^^^^^^^^^^^^^^^^^^^^^^^^^^^^^^^^^^^^^^^^^
  File "D:\Azamat\projects\back-end\learning\байэл\baia_messanger\venv\Lib\site-packages\django\views\decorators\csrf.py", line 65, in _view_wrapper
    return view_func(request, *args, **kwargs)
           ^^^^^^^^^^^^^^^^^^^^^^^^^^^^^^^^^^^
  File "D:\Azamat\projects\back-end\learning\байэл\baia_messanger\venv\Lib\site-packages\django\views\generic\base.py", line 104, in view
    return self.dispatch(request, *args, **kwargs)
           ^^^^^^^^^^^^^^^^^^^^^^^^^^^^^^^^^^^^^^^
  File "D:\Azamat\projects\back-end\learning\байэл\baia_messanger\venv\Lib\site-packages\rest_framework\views.py", line 509, in dispatch
    response = self.handle_exception(exc)
               ^^^^^^^^^^^^^^^^^^^^^^^^^^
  File "D:\Azamat\projects\back-end\learning\байэл\baia_messanger\venv\Lib\site-packages\rest_framework\views.py", line 469, in handle_exception
    self.raise_uncaught_exception(exc)
  File "D:\Azamat\projects\back-end\learning\байэл\baia_messanger\venv\Lib\site-packages\rest_framework\views.py", line 480, in raise_uncaught_exception
    raise exc
  File "D:\Azamat\projects\back-end\learning\байэл\baia_messanger\venv\Lib\site-packages\rest_framework\views.py", line 506, in dispatch
    response = handler(request, *args, **kwargs)
               ^^^^^^^^^^^^^^^^^^^^^^^^^^^^^^^^^
  File "D:\Azamat\projects\back-end\learning\байэл\baia_messanger\api\v1\views\views.py", line 23, in patch
    user = self.get_object()
           ^^^^^^^^^^^^^^^^^
  File "D:\Azamat\projects\back-end\learning\байэл\baia_messanger\venv\Lib\site-packages\rest_framework\generics.py", line 87, in get_object
    queryset = self.filter_queryset(self.get_queryset())
                                    ^^^^^^^^^^^^^^^^^^^
  File "D:\Azamat\projects\back-end\learning\байэл\baia_messanger\venv\Lib\site-packages\rest_framework\generics.py", line 67, in get_queryset
    assert self.queryset is not None, (
           ^^^^^^^^^^^^^^^^^^^^^^^^^
AssertionError: 'UserUpdateView' should either include a `queryset` attribute, or override the `get_queryset()` method.
ERROR 2024-11-29 16:53:53,316 basehttp 1316 9828 "PATCH /api/user/update/ HTTP/1.1" 500 22432
ERROR 2024-11-29 16:56:05,941 log 13992 10136 Internal Server Error: /api/user/update/
Traceback (most recent call last):
  File "D:\Azamat\projects\back-end\learning\байэл\baia_messanger\venv\Lib\site-packages\django\core\handlers\exception.py", line 55, in inner
    response = get_response(request)
               ^^^^^^^^^^^^^^^^^^^^^
  File "D:\Azamat\projects\back-end\learning\байэл\baia_messanger\venv\Lib\site-packages\django\core\handlers\base.py", line 197, in _get_response
    response = wrapped_callback(request, *callback_args, **callback_kwargs)
               ^^^^^^^^^^^^^^^^^^^^^^^^^^^^^^^^^^^^^^^^^^^^^^^^^^^^^^^^^^^^
  File "D:\Azamat\projects\back-end\learning\байэл\baia_messanger\venv\Lib\site-packages\django\views\decorators\csrf.py", line 65, in _view_wrapper
    return view_func(request, *args, **kwargs)
           ^^^^^^^^^^^^^^^^^^^^^^^^^^^^^^^^^^^
  File "D:\Azamat\projects\back-end\learning\байэл\baia_messanger\venv\Lib\site-packages\django\views\generic\base.py", line 104, in view
    return self.dispatch(request, *args, **kwargs)
           ^^^^^^^^^^^^^^^^^^^^^^^^^^^^^^^^^^^^^^^
  File "D:\Azamat\projects\back-end\learning\байэл\baia_messanger\venv\Lib\site-packages\rest_framework\views.py", line 509, in dispatch
    response = self.handle_exception(exc)
               ^^^^^^^^^^^^^^^^^^^^^^^^^^
  File "D:\Azamat\projects\back-end\learning\байэл\baia_messanger\venv\Lib\site-packages\rest_framework\views.py", line 469, in handle_exception
    self.raise_uncaught_exception(exc)
  File "D:\Azamat\projects\back-end\learning\байэл\baia_messanger\venv\Lib\site-packages\rest_framework\views.py", line 480, in raise_uncaught_exception
    raise exc
  File "D:\Azamat\projects\back-end\learning\байэл\baia_messanger\venv\Lib\site-packages\rest_framework\views.py", line 506, in dispatch
    response = handler(request, *args, **kwargs)
               ^^^^^^^^^^^^^^^^^^^^^^^^^^^^^^^^^
  File "D:\Azamat\projects\back-end\learning\байэл\baia_messanger\venv\Lib\site-packages\rest_framework\generics.py", line 230, in put
    return self.update(request, *args, **kwargs)
           ^^^^^^^^^^^^^^^^^^^^^^^^^^^^^^^^^^^^^
  File "D:\Azamat\projects\back-end\learning\байэл\baia_messanger\venv\Lib\site-packages\rest_framework\mixins.py", line 65, in update
    instance = self.get_object()
               ^^^^^^^^^^^^^^^^^
  File "D:\Azamat\projects\back-end\learning\байэл\baia_messanger\venv\Lib\site-packages\rest_framework\generics.py", line 87, in get_object
    queryset = self.filter_queryset(self.get_queryset())
                                    ^^^^^^^^^^^^^^^^^^^
  File "D:\Azamat\projects\back-end\learning\байэл\baia_messanger\venv\Lib\site-packages\rest_framework\generics.py", line 67, in get_queryset
    assert self.queryset is not None, (
           ^^^^^^^^^^^^^^^^^^^^^^^^^
AssertionError: 'UserUpdateView' should either include a `queryset` attribute, or override the `get_queryset()` method.
ERROR 2024-11-29 16:56:05,946 basehttp 13992 10136 "PUT /api/user/update/ HTTP/1.1" 500 22702
ERROR 2024-11-29 17:03:21,125 log 13992 14896 Internal Server Error: /api/user/update/
Traceback (most recent call last):
  File "D:\Azamat\projects\back-end\learning\байэл\baia_messanger\venv\Lib\site-packages\django\core\handlers\exception.py", line 55, in inner
    response = get_response(request)
               ^^^^^^^^^^^^^^^^^^^^^
  File "D:\Azamat\projects\back-end\learning\байэл\baia_messanger\venv\Lib\site-packages\django\core\handlers\base.py", line 197, in _get_response
    response = wrapped_callback(request, *callback_args, **callback_kwargs)
               ^^^^^^^^^^^^^^^^^^^^^^^^^^^^^^^^^^^^^^^^^^^^^^^^^^^^^^^^^^^^
  File "D:\Azamat\projects\back-end\learning\байэл\baia_messanger\venv\Lib\site-packages\django\views\decorators\csrf.py", line 65, in _view_wrapper
    return view_func(request, *args, **kwargs)
           ^^^^^^^^^^^^^^^^^^^^^^^^^^^^^^^^^^^
  File "D:\Azamat\projects\back-end\learning\байэл\baia_messanger\venv\Lib\site-packages\django\views\generic\base.py", line 104, in view
    return self.dispatch(request, *args, **kwargs)
           ^^^^^^^^^^^^^^^^^^^^^^^^^^^^^^^^^^^^^^^
  File "D:\Azamat\projects\back-end\learning\байэл\baia_messanger\venv\Lib\site-packages\rest_framework\views.py", line 509, in dispatch
    response = self.handle_exception(exc)
               ^^^^^^^^^^^^^^^^^^^^^^^^^^
  File "D:\Azamat\projects\back-end\learning\байэл\baia_messanger\venv\Lib\site-packages\rest_framework\views.py", line 469, in handle_exception
    self.raise_uncaught_exception(exc)
  File "D:\Azamat\projects\back-end\learning\байэл\baia_messanger\venv\Lib\site-packages\rest_framework\views.py", line 480, in raise_uncaught_exception
    raise exc
  File "D:\Azamat\projects\back-end\learning\байэл\baia_messanger\venv\Lib\site-packages\rest_framework\views.py", line 506, in dispatch
    response = handler(request, *args, **kwargs)
               ^^^^^^^^^^^^^^^^^^^^^^^^^^^^^^^^^
  File "D:\Azamat\projects\back-end\learning\байэл\baia_messanger\venv\Lib\site-packages\rest_framework\generics.py", line 230, in put
    return self.update(request, *args, **kwargs)
           ^^^^^^^^^^^^^^^^^^^^^^^^^^^^^^^^^^^^^
  File "D:\Azamat\projects\back-end\learning\байэл\baia_messanger\venv\Lib\site-packages\rest_framework\mixins.py", line 65, in update
    instance = self.get_object()
               ^^^^^^^^^^^^^^^^^
  File "D:\Azamat\projects\back-end\learning\байэл\baia_messanger\venv\Lib\site-packages\rest_framework\generics.py", line 87, in get_object
    queryset = self.filter_queryset(self.get_queryset())
                                    ^^^^^^^^^^^^^^^^^^^
  File "D:\Azamat\projects\back-end\learning\байэл\baia_messanger\venv\Lib\site-packages\rest_framework\generics.py", line 67, in get_queryset
    assert self.queryset is not None, (
           ^^^^^^^^^^^^^^^^^^^^^^^^^
AssertionError: 'UserUpdateView' should either include a `queryset` attribute, or override the `get_queryset()` method.
ERROR 2024-11-29 17:03:21,128 basehttp 13992 14896 "PUT /api/user/update/ HTTP/1.1" 500 22702
ERROR 2024-11-29 17:03:24,362 log 13992 14896 Internal Server Error: /api/user/update/
Traceback (most recent call last):
  File "D:\Azamat\projects\back-end\learning\байэл\baia_messanger\venv\Lib\site-packages\django\core\handlers\exception.py", line 55, in inner
    response = get_response(request)
               ^^^^^^^^^^^^^^^^^^^^^
  File "D:\Azamat\projects\back-end\learning\байэл\baia_messanger\venv\Lib\site-packages\django\core\handlers\base.py", line 197, in _get_response
    response = wrapped_callback(request, *callback_args, **callback_kwargs)
               ^^^^^^^^^^^^^^^^^^^^^^^^^^^^^^^^^^^^^^^^^^^^^^^^^^^^^^^^^^^^
  File "D:\Azamat\projects\back-end\learning\байэл\baia_messanger\venv\Lib\site-packages\django\views\decorators\csrf.py", line 65, in _view_wrapper
    return view_func(request, *args, **kwargs)
           ^^^^^^^^^^^^^^^^^^^^^^^^^^^^^^^^^^^
  File "D:\Azamat\projects\back-end\learning\байэл\baia_messanger\venv\Lib\site-packages\django\views\generic\base.py", line 104, in view
    return self.dispatch(request, *args, **kwargs)
           ^^^^^^^^^^^^^^^^^^^^^^^^^^^^^^^^^^^^^^^
  File "D:\Azamat\projects\back-end\learning\байэл\baia_messanger\venv\Lib\site-packages\rest_framework\views.py", line 509, in dispatch
    response = self.handle_exception(exc)
               ^^^^^^^^^^^^^^^^^^^^^^^^^^
  File "D:\Azamat\projects\back-end\learning\байэл\baia_messanger\venv\Lib\site-packages\rest_framework\views.py", line 469, in handle_exception
    self.raise_uncaught_exception(exc)
  File "D:\Azamat\projects\back-end\learning\байэл\baia_messanger\venv\Lib\site-packages\rest_framework\views.py", line 480, in raise_uncaught_exception
    raise exc
  File "D:\Azamat\projects\back-end\learning\байэл\baia_messanger\venv\Lib\site-packages\rest_framework\views.py", line 506, in dispatch
    response = handler(request, *args, **kwargs)
               ^^^^^^^^^^^^^^^^^^^^^^^^^^^^^^^^^
  File "D:\Azamat\projects\back-end\learning\байэл\baia_messanger\venv\Lib\site-packages\rest_framework\generics.py", line 230, in put
    return self.update(request, *args, **kwargs)
           ^^^^^^^^^^^^^^^^^^^^^^^^^^^^^^^^^^^^^
  File "D:\Azamat\projects\back-end\learning\байэл\baia_messanger\venv\Lib\site-packages\rest_framework\mixins.py", line 65, in update
    instance = self.get_object()
               ^^^^^^^^^^^^^^^^^
  File "D:\Azamat\projects\back-end\learning\байэл\baia_messanger\venv\Lib\site-packages\rest_framework\generics.py", line 87, in get_object
    queryset = self.filter_queryset(self.get_queryset())
                                    ^^^^^^^^^^^^^^^^^^^
  File "D:\Azamat\projects\back-end\learning\байэл\baia_messanger\venv\Lib\site-packages\rest_framework\generics.py", line 67, in get_queryset
    assert self.queryset is not None, (
           ^^^^^^^^^^^^^^^^^^^^^^^^^
AssertionError: 'UserUpdateView' should either include a `queryset` attribute, or override the `get_queryset()` method.
ERROR 2024-11-29 17:03:24,365 basehttp 13992 14896 "PUT /api/user/update/ HTTP/1.1" 500 22702
